Workbook

Sheet object_1
B1: Date
B3: Name: | R3: Object#: | S3: 1
B5: BLOCK-A | R5: BLOCK-F
B6: A-01 | R6: F-01
Q7: =IF(ISBLANK(O7),IF(ISBLANK(M7),IF(ISBLANK(K7),IF(ISBLANK(I7),IF(ISBLANK(G7),IF(ISBLANK(E7),0,1),2),3),4),5),6) -> 0 | AG7: =IF(ISBLANK(AE7),IF(ISBLANK(AC7),IF(ISBLANK(AA7),IF(ISBLANK(Y7),IF(ISBLANK(W7),IF(ISBLANK(U7),0,1),2),3),4),5),6) -> 0
C8: 0 | E8: 1 | G8: 2 | I8: 3 | K8: 4 | M8: 5 | O8: 6 | S8: 0 | U8: 1 | W8: 2 | Y8: 3 | AA8: 4 | AC8: 5 | AE8: 6
E10: A-02 | Q10: =IF(ISBLANK(C10),0,Q7) -> 0 | U10: F-02 | AG10: =IF(ISBLANK(S10),0,AG7) -> 0
E12: A-03 | Q12: =IF(ISBLANK(C12),0,Q7) -> 0 | U12: F-03 | AG12: =IF(ISBLANK(S12),0,AG7) -> 0
E14: A-04 | Q14: =IF(ISBLANK(C14),0,Q7) -> 0 | U14: F-04 | AG14: =IF(ISBLANK(S14),0,AG7) -> 0
E16: A-05 | Q16: =IF(ISBLANK(C16),0,Q7) -> 0 | U16: F-05 | AG16: =IF(ISBLANK(S16),0,AG7) -> 0
B19: A-06 | R19: F-06
Q20: =IF(ISBLANK(O20),IF(ISBLANK(M20),IF(ISBLANK(K20),IF(ISBLANK(I20),IF(ISBLANK(G20),IF(ISBLANK(E20),0,1),2),3),4),5),6) -> 0 | AG20: =IF(ISBLANK(AE20),IF(ISBLANK(AC20),IF(ISBLANK(AA20),IF(ISBLANK(Y20),IF(ISBLANK(W20),IF(ISBLANK(U20),0,1),2),3),4),5),6) -> 0
C21: 0 | E21: 1 | G21: 2 | I21: 3 | K21: 4 | M21: 5 | O21: 6 | S21: 0 | U21: 1 | W21: 2 | Y21: 3 | AA21: 4 | AC21: 5 | AE21: 6
E23: A-07 | Q23: =IF(ISBLANK(C23),0,Q20) -> 0 | U23: F-07 | AG23: =IF(ISBLANK(S23),0,AG20) -> 0
E25: A-08 | Q25: =IF(ISBLANK(C25),0,Q20) -> 0 | U25: F-08 | AG25: =IF(ISBLANK(S25),0,AG20) -> 0
E27: A-09 | Q27: =IF(ISBLANK(C27),0,Q20) -> 0 | U27: F-09 | AG27: =IF(ISBLANK(S27),0,AG20) -> 0
E29: A-10 | Q29: =IF(ISBLANK(C29),0,Q20) -> 0 | U29: F-10 | AG29: =IF(ISBLANK(S29),0,AG20) -> 0
B32: A-11 | R32: F-11
Q33: =IF(ISBLANK(O33),IF(ISBLANK(M33),IF(ISBLANK(K33),IF(ISBLANK(I33),IF(ISBLANK(G33),IF(ISBLANK(E33),0,1),2),3),4),5),6) -> 0 | AG33: =IF(ISBLANK(AE33),IF(ISBLANK(AC33),IF(ISBLANK(AA33),IF(ISBLANK(Y33),IF(ISBLANK(W33),IF(ISBLANK(U33),0,1),2),3),4),5),6) -> 0
C34: 0 | E34: 1 | G34: 2 | I34: 3 | K34: 4 | M34: 5 | O34: 6 | S34: 0 | U34: 1 | W34: 2 | Y34: 3 | AA34: 4 | AC34: 5 | AE34: 6
E36: A-12 | Q36: =IF(ISBLANK(C36),0,Q33) -> 0 | U36: F-12 | AG36: =IF(ISBLANK(S36),0,AG33) -> 0
E38: A-13 | Q38: =IF(ISBLANK(C38),0,Q33) -> 0 | U38: F-13 | AG38: =IF(ISBLANK(S38),0,AG33) -> 0
E40: A-14 | Q40: =IF(ISBLANK(C40),0,Q33) -> 0 | U40: F-14 | AG40: =IF(ISBLANK(S40),0,AG33) -> 0
E42: A-15 | Q42: =IF(ISBLANK(C42),0,Q33) -> 0 | U42: F-15 | AG42: =IF(ISBLANK(S42),0,AG33) -> 0
B44: A-16 | R44: F-16
Q45: =IF(ISBLANK(O45),IF(ISBLANK(M45),IF(ISBLANK(K45),IF(ISBLANK(I45),IF(ISBLANK(G45),IF(ISBLANK(E45),0,1),2),3),4),5),6) -> 0 | AG45: =IF(ISBLANK(AE45),IF(ISBLANK(AC45),IF(ISBLANK(AA45),IF(ISBLANK(Y45),IF(ISBLANK(W45),IF(ISBLANK(U45),0,1),2),3),4),5),6) -> 0
C46: 0 | E46: 1 | G46: 2 | I46: 3 | K46: 4 | M46: 5 | O46: 6 | S46: 0 | U46: 1 | W46: 2 | Y46: 3 | AA46: 4 | AC46: 5 | AE46: 6
B49: A-17 | R49: F-17
Q50: =IF(ISBLANK(O50),IF(ISBLANK(M50),IF(ISBLANK(K50),IF(ISBLANK(I50),IF(ISBLANK(G50),IF(ISBLANK(E50),0,1),2),3),4),5),6) -> 0 | AG50: =IF(ISBLANK(AE50),IF(ISBLANK(AC50),IF(ISBLANK(AA50),IF(ISBLANK(Y50),IF(ISBLANK(W50),IF(ISBLANK(U50),0,1),2),3),4),5),6) -> 0
C51: 0 | E51: 1 | G51: 2 | I51: 3 | K51: 4 | M51: 5 | O51: 6 | S51: 0 | U51: 1 | W51: 2 | Y51: 3 | AA51: 4 | AC51: 5 | AE51: 6
B53: A-18 | R53: F-18
Q54: =IF(ISBLANK(O54),IF(ISBLANK(M54),IF(ISBLANK(K54),IF(ISBLANK(I54),IF(ISBLANK(G54),IF(ISBLANK(E54),0,1),2),3),4),5),6) -> 0 | AG54: =IF(ISBLANK(AE54),IF(ISBLANK(AC54),IF(ISBLANK(AA54),IF(ISBLANK(Y54),IF(ISBLANK(W54),IF(ISBLANK(U54),0,1),2),3),4),5),6) -> 0
C55: 0 | E55: 1 | G55: 2 | I55: 3 | K55: 4 | M55: 5 | O55: 6 | S55: 0 | U55: 1 | W55: 2 | Y55: 3 | AA55: 4 | AC55: 5 | AE55: 6
B57: A-19 | R57: F-19
Q58: =IF(ISBLANK(O58),IF(ISBLANK(M58),IF(ISBLANK(K58),IF(ISBLANK(I58),IF(ISBLANK(G58),IF(ISBLANK(E58),0,1),2),3),4),5),6) -> 0 | AG58: =IF(ISBLANK(AE58),IF(ISBLANK(AC58),IF(ISBLANK(AA58),IF(ISBLANK(Y58),IF(ISBLANK(W58),IF(ISBLANK(U58),0,1),2),3),4),5),6) -> 0
C59: 0 | E59: 1 | G59: 2 | I59: 3 | K59: 4 | M59: 5 | O59: 6 | S59: 0 | U59: 1 | W59: 2 | Y59: 3 | AA59: 4 | AC59: 5 | AE59: 6
B61: A-20
Q62: =IF(ISBLANK(O62),IF(ISBLANK(M62),IF(ISBLANK(K62),IF(ISBLANK(I62),IF(ISBLANK(G62),IF(ISBLANK(E62),0,1),2),3),4),5),6) -> 0 | AG62: =IF(ISBLANK(AE62),IF(ISBLANK(AC62),IF(ISBLANK(AA62),IF(ISBLANK(Y62),IF(ISBLANK(W62),IF(ISBLANK(U62),0,1),2),3),4),5),6) -> 0
C63: 0 | E63: 1 | G63: 2 | I63: 3 | K63: 4 | M63: 5 | O63: 6
B66: SEC-A4
...

Sheet object_2
B1: Date
B3: Name: | R3: Object#: | S3: 2
B5: BLOCK-A | R5: BLOCK-F
B6: A-01 | R6: F-01
Q7: =IF(ISBLANK(O7),IF(ISBLANK(M7),IF(ISBLANK(K7),IF(ISBLANK(I7),IF(ISBLANK(G7),IF(ISBLANK(E7),0,1),2),3),4),5),6) -> 0 | AG7: =IF(ISBLANK(AE7),IF(ISBLANK(AC7),IF(ISBLANK(AA7),IF(ISBLANK(Y7),IF(ISBLANK(W7),IF(ISBLANK(U7),0,1),2),3),4),5),6) -> 0
C8: 0 | E8: 1 | G8: 2 | I8: 3 | K8: 4 | M8: 5 | O8: 6 | S8: 0 | U8: 1 | W8: 2 | Y8: 3 | AA8: 4 | AC8: 5 | AE8: 6
E10: A-02 | Q10: =IF(ISBLANK(C10),0,Q7) -> 0 | U10: F-02 | AG10: =IF(ISBLANK(S10),0,AG7) -> 0
E12: A-03 | Q12: =IF(ISBLANK(C12),0,Q7) -> 0 | U12: F-03 | AG12: =IF(ISBLANK(S12),0,AG7) -> 0
E14: A-04 | Q14: =IF(ISBLANK(C14),0,Q7) -> 0 | U14: F-04 | AG14: =IF(ISBLANK(S14),0,AG7) -> 0
E16: A-05 | Q16: =IF(ISBLANK(C16),0,Q7) -> 0 | U16: F-05 | AG16: =IF(ISBLANK(S16),0,AG7) -> 0
B19: A-06 | R19: F-06
Q20: =IF(ISBLANK(O20),IF(ISBLANK(M20),IF(ISBLANK(K20),IF(ISBLANK(I20),IF(ISBLANK(G20),IF(ISBLANK(E20),0,1),2),3),4),5),6) -> 0 | AG20: =IF(ISBLANK(AE20),IF(ISBLANK(AC20),IF(ISBLANK(AA20),IF(ISBLANK(Y20),IF(ISBLANK(W20),IF(ISBLANK(U20),0,1),2),3),4),5),6) -> 0
C21: 0 | E21: 1 | G21: 2 | I21: 3 | K21: 4 | M21: 5 | O21: 6 | S21: 0 | U21: 1 | W21: 2 | Y21: 3 | AA21: 4 | AC21: 5 | AE21: 6
E23: A-07 | Q23: =IF(ISBLANK(C23),0,Q20) -> 0 | U23: F-07 | AG23: =IF(ISBLANK(S23),0,AG20) -> 0
E25: A-08 | Q25: =IF(ISBLANK(C25),0,Q20) -> 0 | U25: F-08 | AG25: =IF(ISBLANK(S25),0,AG20) -> 0
E27: A-09 | Q27: =IF(ISBLANK(C27),0,Q20) -> 0 | U27: F-09 | AG27: =IF(ISBLANK(S27),0,AG20) -> 0
E29: A-10 | Q29: =IF(ISBLANK(C29),0,Q20) -> 0 | U29: F-10 | AG29: =IF(ISBLANK(S29),0,AG20) -> 0
B32: A-11 | R32: F-11
Q33: =IF(ISBLANK(O33),IF(ISBLANK(M33),IF(ISBLANK(K33),IF(ISBLANK(I33),IF(ISBLANK(G33),IF(ISBLANK(E33),0,1),2),3),4),5),6) -> 0 | AG33: =IF(ISBLANK(AE33),IF(ISBLANK(AC33),IF(ISBLANK(AA33),IF(ISBLANK(Y33),IF(ISBLANK(W33),IF(ISBLANK(U33),0,1),2),3),4),5),6) -> 0
C34: 0 | E34: 1 | G34: 2 | I34: 3 | K34: 4 | M34: 5 | O34: 6 | S34: 0 | U34: 1 | W34: 2 | Y34: 3 | AA34: 4 | AC34: 5 | AE34: 6
E36: A-12 | Q36: =IF(ISBLANK(C36),0,Q33) -> 0 | U36: F-12 | AG36: =IF(ISBLANK(S36),0,AG33) -> 0
E38: A-13 | Q38: =IF(ISBLANK(C38),0,Q33) -> 0 | U38: F-13 | AG38: =IF(ISBLANK(S38),0,AG33) -> 0
E40: A-14 | Q40: =IF(ISBLANK(C40),0,Q33) -> 0 | U40: F-14 | AG40: =IF(ISBLANK(S40),0,AG33) -> 0
E42: A-15 | Q42: =IF(ISBLANK(C42),0,Q33) -> 0 | U42: F-15 | AG42: =IF(ISBLANK(S42),0,AG33) -> 0
B44: A-16 | R44: F-16
Q45: =IF(ISBLANK(O45),IF(ISBLANK(M45),IF(ISBLANK(K45),IF(ISBLANK(I45),IF(ISBLANK(G45),IF(ISBLANK(E45),0,1),2),3),4),5),6) -> 0 | AG45: =IF(ISBLANK(AE45),IF(ISBLANK(AC45),IF(ISBLANK(AA45),IF(ISBLANK(Y45),IF(ISBLANK(W45),IF(ISBLANK(U45),0,1),2),3),4),5),6) -> 0
C46: 0 | E46: 1 | G46: 2 | I46: 3 | K46: 4 | M46: 5 | O46: 6 | S46: 0 | U46: 1 | W46: 2 | Y46: 3 | AA46: 4 | AC46: 5 | AE46: 6
B49: A-17 | R49: F-17
Q50: =IF(ISBLANK(O50),IF(ISBLANK(M50),IF(ISBLANK(K50),IF(ISBLANK(I50),IF(ISBLANK(G50),IF(ISBLANK(E50),0,1),2),3),4),5),6) -> 0 | AG50: =IF(ISBLANK(AE50),IF(ISBLANK(AC50),IF(ISBLANK(AA50),IF(ISBLANK(Y50),IF(ISBLANK(W50),IF(ISBLANK(U50),0,1),2),3),4),5),6) -> 0
C51: 0 | E51: 1 | G51: 2 | I51: 3 | K51: 4 | M51: 5 | O51: 6 | S51: 0 | U51: 1 | W51: 2 | Y51: 3 | AA51: 4 | AC51: 5 | AE51: 6
B53: A-18 | R53: F-18
Q54: =IF(ISBLANK(O54),IF(ISBLANK(M54),IF(ISBLANK(K54),IF(ISBLANK(I54),IF(ISBLANK(G54),IF(ISBLANK(E54),0,1),2),3),4),5),6) -> 0 | AG54: =IF(ISBLANK(AE54),IF(ISBLANK(AC54),IF(ISBLANK(AA54),IF(ISBLANK(Y54),IF(ISBLANK(W54),IF(ISBLANK(U54),0,1),2),3),4),5),6) -> 0
C55: 0 | E55: 1 | G55: 2 | I55: 3 | K55: 4 | M55: 5 | O55: 6 | S55: 0 | U55: 1 | W55: 2 | Y55: 3 | AA55: 4 | AC55: 5 | AE55: 6
B57: A-19 | R57: F-19
Q58: =IF(ISBLANK(O58),IF(ISBLANK(M58),IF(ISBLANK(K58),IF(ISBLANK(I58),IF(ISBLANK(G58),IF(ISBLANK(E58),0,1),2),3),4),5),6) -> 0 | AG58: =IF(ISBLANK(AE58),IF(ISBLANK(AC58),IF(ISBLANK(AA58),IF(ISBLANK(Y58),IF(ISBLANK(W58),IF(ISBLANK(U58),0,1),2),3),4),5),6) -> 0
C59: 0 | E59: 1 | G59: 2 | I59: 3 | K59: 4 | M59: 5 | O59: 6 | S59: 0 | U59: 1 | W59: 2 | Y59: 3 | AA59: 4 | AC59: 5 | AE59: 6
B61: A-20
Q62: =IF(ISBLANK(O62),IF(ISBLANK(M62),IF(ISBLANK(K62),IF(ISBLANK(I62),IF(ISBLANK(G62),IF(ISBLANK(E62),0,1),2),3),4),5),6) -> 0 | AG62: =IF(ISBLANK(AE62),IF(ISBLANK(AC62),IF(ISBLANK(AA62),IF(ISBLANK(Y62),IF(ISBLANK(W62),IF(ISBLANK(U62),0,1),2),3),4),5),6) -> 0
C63: 0 | E63: 1 | G63: 2 | I63: 3 | K63: 4 | M63: 5 | O63: 6
B66: SEC-A4
...

Sheet object_3
B1: Date
B3: Name: | R3: Object#: | S3: 3
B5: BLOCK-A | R5: BLOCK-F
B6: A-01 | R6: F-01
Q7: =IF(ISBLANK(O7),IF(ISBLANK(M7),IF(ISBLANK(K7),IF(ISBLANK(I7),IF(ISBLANK(G7),IF(ISBLANK(E7),0,1),2),3),4),5),6) -> 0 | AG7: =IF(ISBLANK(AE7),IF(ISBLANK(AC7),IF(ISBLANK(AA7),IF(ISBLANK(Y7),IF(ISBLANK(W7),IF(ISBLANK(U7),0,1),2),3),4),5),6) -> 0
C8: 0 | E8: 1 | G8: 2 | I8: 3 | K8: 4 | M8: 5 | O8: 6 | S8: 0 | U8: 1 | W8: 2 | Y8: 3 | AA8: 4 | AC8: 5 | AE8: 6
E10: A-02 | Q10: =IF(ISBLANK(C10),0,Q7) -> 0 | U10: F-02 | AG10: =IF(ISBLANK(S10),0,AG7) -> 0
E12: A-03 | Q12: =IF(ISBLANK(C12),0,Q7) -> 0 | U12: F-03 | AG12: =IF(ISBLANK(S12),0,AG7) -> 0
E14: A-04 | Q14: =IF(ISBLANK(C14),0,Q7) -> 0 | U14: F-04 | AG14: =IF(ISBLANK(S14),0,AG7) -> 0
E16: A-05 | Q16: =IF(ISBLANK(C16),0,Q7) -> 0 | U16: F-05 | AG16: =IF(ISBLANK(S16),0,AG7) -> 0
B19: A-06 | R19: F-06
Q20: =IF(ISBLANK(O20),IF(ISBLANK(M20),IF(ISBLANK(K20),IF(ISBLANK(I20),IF(ISBLANK(G20),IF(ISBLANK(E20),0,1),2),3),4),5),6) -> 0 | AG20: =IF(ISBLANK(AE20),IF(ISBLANK(AC20),IF(ISBLANK(AA20),IF(ISBLANK(Y20),IF(ISBLANK(W20),IF(ISBLANK(U20),0,1),2),3),4),5),6) -> 0
C21: 0 | E21: 1 | G21: 2 | I21: 3 | K21: 4 | M21: 5 | O21: 6 | S21: 0 | U21: 1 | W21: 2 | Y21: 3 | AA21: 4 | AC21: 5 | AE21: 6
E23: A-07 | Q23: =IF(ISBLANK(C23),0,Q20) -> 0 | U23: F-07 | AG23: =IF(ISBLANK(S23),0,AG20) -> 0
E25: A-08 | Q25: =IF(ISBLANK(C25),0,Q20) -> 0 | U25: F-08 | AG25: =IF(ISBLANK(S25),0,AG20) -> 0
E27: A-09 | Q27: =IF(ISBLANK(C27),0,Q20) -> 0 | U27: F-09 | AG27: =IF(ISBLANK(S27),0,AG20) -> 0
E29: A-10 | Q29: =IF(ISBLANK(C29),0,Q20) -> 0 | U29: F-10 | AG29: =IF(ISBLANK(S29),0,AG20) -> 0
B32: A-11 | R32: F-11
Q33: =IF(ISBLANK(O33),IF(ISBLANK(M33),IF(ISBLANK(K33),IF(ISBLANK(I33),IF(ISBLANK(G33),IF(ISBLANK(E33),0,1),2),3),4),5),6) -> 0 | AG33: =IF(ISBLANK(AE33),IF(ISBLANK(AC33),IF(ISBLANK(AA33),IF(ISBLANK(Y33),IF(ISBLANK(W33),IF(ISBLANK(U33),0,1),2),3),4),5),6) -> 0
C34: 0 | E34: 1 | G34: 2 | I34: 3 | K34: 4 | M34: 5 | O34: 6 | S34: 0 | U34: 1 | W34: 2 | Y34: 3 | AA34: 4 | AC34: 5 | AE34: 6
E36: A-12 | Q36: =IF(ISBLANK(C36),0,Q33) -> 0 | U36: F-12 | AG36: =IF(ISBLANK(S36),0,AG33) -> 0
E38: A-13 | Q38: =IF(ISBLANK(C38),0,Q33) -> 0 | U38: F-13 | AG38: =IF(ISBLANK(S38),0,AG33) -> 0
E40: A-14 | Q40: =IF(ISBLANK(C40),0,Q33) -> 0 | U40: F-14 | AG40: =IF(ISBLANK(S40),0,AG33) -> 0
E42: A-15 | Q42: =IF(ISBLANK(C42),0,Q33) -> 0 | U42: F-15 | AG42: =IF(ISBLANK(S42),0,AG33) -> 0
B44: A-16 | R44: F-16
Q45: =IF(ISBLANK(O45),IF(ISBLANK(M45),IF(ISBLANK(K45),IF(ISBLANK(I45),IF(ISBLANK(G45),IF(ISBLANK(E45),0,1),2),3),4),5),6) -> 0 | AG45: =IF(ISBLANK(AE45),IF(ISBLANK(AC45),IF(ISBLANK(AA45),IF(ISBLANK(Y45),IF(ISBLANK(W45),IF(ISBLANK(U45),0,1),2),3),4),5),6) -> 0
C46: 0 | E46: 1 | G46: 2 | I46: 3 | K46: 4 | M46: 5 | O46: 6 | S46: 0 | U46: 1 | W46: 2 | Y46: 3 | AA46: 4 | AC46: 5 | AE46: 6
B49: A-17 | R49: F-17
Q50: =IF(ISBLANK(O50),IF(ISBLANK(M50),IF(ISBLANK(K50),IF(ISBLANK(I50),IF(ISBLANK(G50),IF(ISBLANK(E50),0,1),2),3),4),5),6) -> 0 | AG50: =IF(ISBLANK(AE50),IF(ISBLANK(AC50),IF(ISBLANK(AA50),IF(ISBLANK(Y50),IF(ISBLANK(W50),IF(ISBLANK(U50),0,1),2),3),4),5),6) -> 0
C51: 0 | E51: 1 | G51: 2 | I51: 3 | K51: 4 | M51: 5 | O51: 6 | S51: 0 | U51: 1 | W51: 2 | Y51: 3 | AA51: 4 | AC51: 5 | AE51: 6
B53: A-18 | R53: F-18
Q54: =IF(ISBLANK(O54),IF(ISBLANK(M54),IF(ISBLANK(K54),IF(ISBLANK(I54),IF(ISBLANK(G54),IF(ISBLANK(E54),0,1),2),3),4),5),6) -> 0 | AG54: =IF(ISBLANK(AE54),IF(ISBLANK(AC54),IF(ISBLANK(AA54),IF(ISBLANK(Y54),IF(ISBLANK(W54),IF(ISBLANK(U54),0,1),2),3),4),5),6) -> 0
C55: 0 | E55: 1 | G55: 2 | I55: 3 | K55: 4 | M55: 5 | O55: 6 | S55: 0 | U55: 1 | W55: 2 | Y55: 3 | AA55: 4 | AC55: 5 | AE55: 6
B57: A-19 | R57: F-19
Q58: =IF(ISBLANK(O58),IF(ISBLANK(M58),IF(ISBLANK(K58),IF(ISBLANK(I58),IF(ISBLANK(G58),IF(ISBLANK(E58),0,1),2),3),4),5),6) -> 0 | AG58: =IF(ISBLANK(AE58),IF(ISBLANK(AC58),IF(ISBLANK(AA58),IF(ISBLANK(Y58),IF(ISBLANK(W58),IF(ISBLANK(U58),0,1),2),3),4),5),6) -> 0
C59: 0 | E59: 1 | G59: 2 | I59: 3 | K59: 4 | M59: 5 | O59: 6 | S59: 0 | U59: 1 | W59: 2 | Y59: 3 | AA59: 4 | AC59: 5 | AE59: 6
B61: A-20
Q62: =IF(ISBLANK(O62),IF(ISBLANK(M62),IF(ISBLANK(K62),IF(ISBLANK(I62),IF(ISBLANK(G62),IF(ISBLANK(E62),0,1),2),3),4),5),6) -> 0 | AG62: =IF(ISBLANK(AE62),IF(ISBLANK(AC62),IF(ISBLANK(AA62),IF(ISBLANK(Y62),IF(ISBLANK(W62),IF(ISBLANK(U62),0,1),2),3),4),5),6) -> 0
C63: 0 | E63: 1 | G63: 2 | I63: 3 | K63: 4 | M63: 5 | O63: 6
B66: SEC-A4
...

Sheet object_4
B1: Date
B3: Name: | R3: Object#: | S3: 4
B5: BLOCK-A | R5: BLOCK-F
B6: A-01 | R6: F-01
Q7: =IF(ISBLANK(O7),IF(ISBLANK(M7),IF(ISBLANK(K7),IF(ISBLANK(I7),IF(ISBLANK(G7),IF(ISBLANK(E7),0,1),2),3),4),5),6) -> 0 | AG7: =IF(ISBLANK(AE7),IF(ISBLANK(AC7),IF(ISBLANK(AA7),IF(ISBLANK(Y7),IF(ISBLANK(W7),IF(ISBLANK(U7),0,1),2),3),4),5),6) -> 0
C8: 0 | E8: 1 | G8: 2 | I8: 3 | K8: 4 | M8: 5 | O8: 6 | S8: 0 | U8: 1 | W8: 2 | Y8: 3 | AA8: 4 | AC8: 5 | AE8: 6
E10: A-02 | Q10: =IF(ISBLANK(C10),0,Q7) -> 0 | U10: F-02 | AG10: =IF(ISBLANK(S10),0,AG7) -> 0
E12: A-03 | Q12: =IF(ISBLANK(C12),0,Q7) -> 0 | U12: F-03 | AG12: =IF(ISBLANK(S12),0,AG7) -> 0
E14: A-04 | Q14: =IF(ISBLANK(C14),0,Q7) -> 0 | U14: F-04 | AG14: =IF(ISBLANK(S14),0,AG7) -> 0
E16: A-05 | Q16: =IF(ISBLANK(C16),0,Q7) -> 0 | U16: F-05 | AG16: =IF(ISBLANK(S16),0,AG7) -> 0
B19: A-06 | R19: F-06
Q20: =IF(ISBLANK(O20),IF(ISBLANK(M20),IF(ISBLANK(K20),IF(ISBLANK(I20),IF(ISBLANK(G20),IF(ISBLANK(E20),0,1),2),3),4),5),6) -> 0 | AG20: =IF(ISBLANK(AE20),IF(ISBLANK(AC20),IF(ISBLANK(AA20),IF(ISBLANK(Y20),IF(ISBLANK(W20),IF(ISBLANK(U20),0,1),2),3),4),5),6) -> 0
C21: 0 | E21: 1 | G21: 2 | I21: 3 | K21: 4 | M21: 5 | O21: 6 | S21: 0 | U21: 1 | W21: 2 | Y21: 3 | AA21: 4 | AC21: 5 | AE21: 6
E23: A-07 | Q23: =IF(ISBLANK(C23),0,Q20) -> 0 | U23: F-07 | AG23: =IF(ISBLANK(S23),0,AG20) -> 0
E25: A-08 | Q25: =IF(ISBLANK(C25),0,Q20) -> 0 | U25: F-08 | AG25: =IF(ISBLANK(S25),0,AG20) -> 0
E27: A-09 | Q27: =IF(ISBLANK(C27),0,Q20) -> 0 | U27: F-09 | AG27: =IF(ISBLANK(S27),0,AG20) -> 0
E29: A-10 | Q29: =IF(ISBLANK(C29),0,Q20) -> 0 | U29: F-10 | AG29: =IF(ISBLANK(S29),0,AG20) -> 0
B32: A-11 | R32: F-11
Q33: =IF(ISBLANK(O33),IF(ISBLANK(M33),IF(ISBLANK(K33),IF(ISBLANK(I33),IF(ISBLANK(G33),IF(ISBLANK(E33),0,1),2),3),4),5),6) -> 0 | AG33: =IF(ISBLANK(AE33),IF(ISBLANK(AC33),IF(ISBLANK(AA33),IF(ISBLANK(Y33),IF(ISBLANK(W33),IF(ISBLANK(U33),0,1),2),3),4),5),6) -> 0
C34: 0 | E34: 1 | G34: 2 | I34: 3 | K34: 4 | M34: 5 | O34: 6 | S34: 0 | U34: 1 | W34: 2 | Y34: 3 | AA34: 4 | AC34: 5 | AE34: 6
E36: A-12 | Q36: =IF(ISBLANK(C36),0,Q33) -> 0 | U36: F-12 | AG36: =IF(ISBLANK(S36),0,AG33) -> 0
E38: A-13 | Q38: =IF(ISBLANK(C38),0,Q33) -> 0 | U38: F-13 | AG38: =IF(ISBLANK(S38),0,AG33) -> 0
E40: A-14 | Q40: =IF(ISBLANK(C40),0,Q33) -> 0 | U40: F-14 | AG40: =IF(ISBLANK(S40),0,AG33) -> 0
E42: A-15 | Q42: =IF(ISBLANK(C42),0,Q33) -> 0 | U42: F-15 | AG42: =IF(ISBLANK(S42),0,AG33) -> 0
B44: A-16 | R44: F-16
Q45: =IF(ISBLANK(O45),IF(ISBLANK(M45),IF(ISBLANK(K45),IF(ISBLANK(I45),IF(ISBLANK(G45),IF(ISBLANK(E45),0,1),2),3),4),5),6) -> 0 | AG45: =IF(ISBLANK(AE45),IF(ISBLANK(AC45),IF(ISBLANK(AA45),IF(ISBLANK(Y45),IF(ISBLANK(W45),IF(ISBLANK(U45),0,1),2),3),4),5),6) -> 0
C46: 0 | E46: 1 | G46: 2 | I46: 3 | K46: 4 | M46: 5 | O46: 6 | S46: 0 | U46: 1 | W46: 2 | Y46: 3 | AA46: 4 | AC46: 5 | AE46: 6
B49: A-17 | R49: F-17
Q50: =IF(ISBLANK(O50),IF(ISBLANK(M50),IF(ISBLANK(K50),IF(ISBLANK(I50),IF(ISBLANK(G50),IF(ISBLANK(E50),0,1),2),3),4),5),6) -> 0 | AG50: =IF(ISBLANK(AE50),IF(ISBLANK(AC50),IF(ISBLANK(AA50),IF(ISBLANK(Y50),IF(ISBLANK(W50),IF(ISBLANK(U50),0,1),2),3),4),5),6) -> 0
C51: 0 | E51: 1 | G51: 2 | I51: 3 | K51: 4 | M51: 5 | O51: 6 | S51: 0 | U51: 1 | W51: 2 | Y51: 3 | AA51: 4 | AC51: 5 | AE51: 6
B53: A-18 | R53: F-18
Q54: =IF(ISBLANK(O54),IF(ISBLANK(M54),IF(ISBLANK(K54),IF(ISBLANK(I54),IF(ISBLANK(G54),IF(ISBLANK(E54),0,1),2),3),4),5),6) -> 0 | AG54: =IF(ISBLANK(AE54),IF(ISBLANK(AC54),IF(ISBLANK(AA54),IF(ISBLANK(Y54),IF(ISBLANK(W54),IF(ISBLANK(U54),0,1),2),3),4),5),6) -> 0
C55: 0 | E55: 1 | G55: 2 | I55: 3 | K55: 4 | M55: 5 | O55: 6 | S55: 0 | U55: 1 | W55: 2 | Y55: 3 | AA55: 4 | AC55: 5 | AE55: 6
B57: A-19 | R57: F-19
Q58: =IF(ISBLANK(O58),IF(ISBLANK(M58),IF(ISBLANK(K58),IF(ISBLANK(I58),IF(ISBLANK(G58),IF(ISBLANK(E58),0,1),2),3),4),5),6) -> 0 | AG58: =IF(ISBLANK(AE58),IF(ISBLANK(AC58),IF(ISBLANK(AA58),IF(ISBLANK(Y58),IF(ISBLANK(W58),IF(ISBLANK(U58),0,1),2),3),4),5),6) -> 0
C59: 0 | E59: 1 | G59: 2 | I59: 3 | K59: 4 | M59: 5 | O59: 6 | S59: 0 | U59: 1 | W59: 2 | Y59: 3 | AA59: 4 | AC59: 5 | AE59: 6
B61: A-20
Q62: =IF(ISBLANK(O62),IF(ISBLANK(M62),IF(ISBLANK(K62),IF(ISBLANK(I62),IF(ISBLANK(G62),IF(ISBLANK(E62),0,1),2),3),4),5),6) -> 0 | AG62: =IF(ISBLANK(AE62),IF(ISBLANK(AC62),IF(ISBLANK(AA62),IF(ISBLANK(Y62),IF(ISBLANK(W62),IF(ISBLANK(U62),0,1),2),3),4),5),6) -> 0
C63: 0 | E63: 1 | G63: 2 | I63: 3 | K63: 4 | M63: 5 | O63: 6
B66: SEC-A4
...

Sheet object_5
B1: Date
B3: Name: | R3: Object#: | S3: 5
B5: BLOCK-A | R5: BLOCK-F
B6: A-01 | R6: F-01
Q7: =IF(ISBLANK(O7),IF(ISBLANK(M7),IF(ISBLANK(K7),IF(ISBLANK(I7),IF(ISBLANK(G7),IF(ISBLANK(E7),0,1),2),3),4),5),6) -> 0 | AG7: =IF(ISBLANK(AE7),IF(ISBLANK(AC7),IF(ISBLANK(AA7),IF(ISBLANK(Y7),IF(ISBLANK(W7),IF(ISBLANK(U7),0,1),2),3),4),5),6) -> 0
C8: 0 | E8: 1 | G8: 2 | I8: 3 | K8: 4 | M8: 5 | O8: 6 | S8: 0 | U8: 1 | W8: 2 | Y8: 3 | AA8: 4 | AC8: 5 | AE8: 6
E10: A-02 | Q10: =IF(ISBLANK(C10),0,Q7) -> 0 | U10: F-02 | AG10: =IF(ISBLANK(S10),0,AG7) -> 0
E12: A-03 | Q12: =IF(ISBLANK(C12),0,Q7) -> 0 | U12: F-03 | AG12: =IF(ISBLANK(S12),0,AG7) -> 0
E14: A-04 | Q14: =IF(ISBLANK(C14),0,Q7) -> 0 | U14: F-04 | AG14: =IF(ISBLANK(S14),0,AG7) -> 0
E16: A-05 | Q16: =IF(ISBLANK(C16),0,Q7) -> 0 | U16: F-05 | AG16: =IF(ISBLANK(S16),0,AG7) -> 0
B19: A-06 | R19: F-06
Q20: =IF(ISBLANK(O20),IF(ISBLANK(M20),IF(ISBLANK(K20),IF(ISBLANK(I20),IF(ISBLANK(G20),IF(ISBLANK(E20),0,1),2),3),4),5),6) -> 0 | AG20: =IF(ISBLANK(AE20),IF(ISBLANK(AC20),IF(ISBLANK(AA20),IF(ISBLANK(Y20),IF(ISBLANK(W20),IF(ISBLANK(U20),0,1),2),3),4),5),6) -> 0
C21: 0 | E21: 1 | G21: 2 | I21: 3 | K21: 4 | M21: 5 | O21: 6 | S21: 0 | U21: 1 | W21: 2 | Y21: 3 | AA21: 4 | AC21: 5 | AE21: 6
E23: A-07 | Q23: =IF(ISBLANK(C23),0,Q20) -> 0 | U23: F-07 | AG23: =IF(ISBLANK(S23),0,AG20) -> 0
E25: A-08 | Q25: =IF(ISBLANK(C25),0,Q20) -> 0 | U25: F-08 | AG25: =IF(ISBLANK(S25),0,AG20) -> 0
E27: A-09 | Q27: =IF(ISBLANK(C27),0,Q20) -> 0 | U27: F-09 | AG27: =IF(ISBLANK(S27),0,AG20) -> 0
E29: A-10 | Q29: =IF(ISBLANK(C29),0,Q20) -> 0 | U29: F-10 | AG29: =IF(ISBLANK(S29),0,AG20) -> 0
B32: A-11 | R32: F-11
Q33: =IF(ISBLANK(O33),IF(ISBLANK(M33),IF(ISBLANK(K33),IF(ISBLANK(I33),IF(ISBLANK(G33),IF(ISBLANK(E33),0,1),2),3),4),5),6) -> 0 | AG33: =IF(ISBLANK(AE33),IF(ISBLANK(AC33),IF(ISBLANK(AA33),IF(ISBLANK(Y33),IF(ISBLANK(W33),IF(ISBLANK(U33),0,1),2),3),4),5),6) -> 0
C34: 0 | E34: 1 | G34: 2 | I34: 3 | K34: 4 | M34: 5 | O34: 6 | S34: 0 | U34: 1 | W34: 2 | Y34: 3 | AA34: 4 | AC34: 5 | AE34: 6
E36: A-12 | Q36: =IF(ISBLANK(C36),0,Q33) -> 0 | U36: F-12 | AG36: =IF(ISBLANK(S36),0,AG33) -> 0
E38: A-13 | Q38: =IF(ISBLANK(C38),0,Q33) -> 0 | U38: F-13 | AG38: =IF(ISBLANK(S38),0,AG33) -> 0
E40: A-14 | Q40: =IF(ISBLANK(C40),0,Q33) -> 0 | U40: F-14 | AG40: =IF(ISBLANK(S40),0,AG33) -> 0
E42: A-15 | Q42: =IF(ISBLANK(C42),0,Q33) -> 0 | U42: F-15 | AG42: =IF(ISBLANK(S42),0,AG33) -> 0
B44: A-16 | R44: F-16
Q45: =IF(ISBLANK(O45),IF(ISBLANK(M45),IF(ISBLANK(K45),IF(ISBLANK(I45),IF(ISBLANK(G45),IF(ISBLANK(E45),0,1),2),3),4),5),6) -> 0 | AG45: =IF(ISBLANK(AE45),IF(ISBLANK(AC45),IF(ISBLANK(AA45),IF(ISBLANK(Y45),IF(ISBLANK(W45),IF(ISBLANK(U45),0,1),2),3),4),5),6) -> 0
C46: 0 | E46: 1 | G46: 2 | I46: 3 | K46: 4 | M46: 5 | O46: 6 | S46: 0 | U46: 1 | W46: 2 | Y46: 3 | AA46: 4 | AC46: 5 | AE46: 6
B49: A-17 | R49: F-17
Q50: =IF(ISBLANK(O50),IF(ISBLANK(M50),IF(ISBLANK(K50),IF(ISBLANK(I50),IF(ISBLANK(G50),IF(ISBLANK(E50),0,1),2),3),4),5),6) -> 0 | AG50: =IF(ISBLANK(AE50),IF(ISBLANK(AC50),IF(ISBLANK(AA50),IF(ISBLANK(Y50),IF(ISBLANK(W50),IF(ISBLANK(U50),0,1),2),3),4),5),6) -> 0
C51: 0 | E51: 1 | G51: 2 | I51: 3 | K51: 4 | M51: 5 | O51: 6 | S51: 0 | U51: 1 | W51: 2 | Y51: 3 | AA51: 4 | AC51: 5 | AE51: 6
B53: A-18 | R53: F-18
Q54: =IF(ISBLANK(O54),IF(ISBLANK(M54),IF(ISBLANK(K54),IF(ISBLANK(I54),IF(ISBLANK(G54),IF(ISBLANK(E54),0,1),2),3),4),5),6) -> 0 | AG54: =IF(ISBLANK(AE54),IF(ISBLANK(AC54),IF(ISBLANK(AA54),IF(ISBLANK(Y54),IF(ISBLANK(W54),IF(ISBLANK(U54),0,1),2),3),4),5),6) -> 0
C55: 0 | E55: 1 | G55: 2 | I55: 3 | K55: 4 | M55: 5 | O55: 6 | S55: 0 | U55: 1 | W55: 2 | Y55: 3 | AA55: 4 | AC55: 5 | AE55: 6
B57: A-19 | R57: F-19
Q58: =IF(ISBLANK(O58),IF(ISBLANK(M58),IF(ISBLANK(K58),IF(ISBLANK(I58),IF(ISBLANK(G58),IF(ISBLANK(E58),0,1),2),3),4),5),6) -> 0 | AG58: =IF(ISBLANK(AE58),IF(ISBLANK(AC58),IF(ISBLANK(AA58),IF(ISBLANK(Y58),IF(ISBLANK(W58),IF(ISBLANK(U58),0,1),2),3),4),5),6) -> 0
C59: 0 | E59: 1 | G59: 2 | I59: 3 | K59: 4 | M59: 5 | O59: 6 | S59: 0 | U59: 1 | W59: 2 | Y59: 3 | AA59: 4 | AC59: 5 | AE59: 6
B61: A-20
Q62: =IF(ISBLANK(O62),IF(ISBLANK(M62),IF(ISBLANK(K62),IF(ISBLANK(I62),IF(ISBLANK(G62),IF(ISBLANK(E62),0,1),2),3),4),5),6) -> 0 | AG62: =IF(ISBLANK(AE62),IF(ISBLANK(AC62),IF(ISBLANK(AA62),IF(ISBLANK(Y62),IF(ISBLANK(W62),IF(ISBLANK(U62),0,1),2),3),4),5),6) -> 0
C63: 0 | E63: 1 | G63: 2 | I63: 3 | K63: 4 | M63: 5 | O63: 6
B66: SEC-A4
...

Sheet object_6
B1: Date
B3: Name: | R3: Object#: | S3: 6
B5: BLOCK-A | R5: BLOCK-F
B6: A-01 | R6: F-01
Q7: =IF(ISBLANK(O7),IF(ISBLANK(M7),IF(ISBLANK(K7),IF(ISBLANK(I7),IF(ISBLANK(G7),IF(ISBLANK(E7),0,1),2),3),4),5),6) -> 0 | AG7: =IF(ISBLANK(AE7),IF(ISBLANK(AC7),IF(ISBLANK(AA7),IF(ISBLANK(Y7),IF(ISBLANK(W7),IF(ISBLANK(U7),0,1),2),3),4),5),6) -> 0
C8: 0 | E8: 1 | G8: 2 | I8: 3 | K8: 4 | M8: 5 | O8: 6 | S8: 0 | U8: 1 | W8: 2 | Y8: 3 | AA8: 4 | AC8: 5 | AE8: 6
E10: A-02 | Q10: =IF(ISBLANK(C10),0,Q7) -> 0 | U10: F-02 | AG10: =IF(ISBLANK(S10),0,AG7) -> 0
E12: A-03 | Q12: =IF(ISBLANK(C12),0,Q7) -> 0 | U12: F-03 | AG12: =IF(ISBLANK(S12),0,AG7) -> 0
E14: A-04 | Q14: =IF(ISBLANK(C14),0,Q7) -> 0 | U14: F-04 | AG14: =IF(ISBLANK(S14),0,AG7) -> 0
E16: A-05 | Q16: =IF(ISBLANK(C16),0,Q7) -> 0 | U16: F-05 | AG16: =IF(ISBLANK(S16),0,AG7) -> 0
B19: A-06 | R19: F-06
Q20: =IF(ISBLANK(O20),IF(ISBLANK(M20),IF(ISBLANK(K20),IF(ISBLANK(I20),IF(ISBLANK(G20),IF(ISBLANK(E20),0,1),2),3),4),5),6) -> 0 | AG20: =IF(ISBLANK(AE20),IF(ISBLANK(AC20),IF(ISBLANK(AA20),IF(ISBLANK(Y20),IF(ISBLANK(W20),IF(ISBLANK(U20),0,1),2),3),4),5),6) -> 0
C21: 0 | E21: 1 | G21: 2 | I21: 3 | K21: 4 | M21: 5 | O21: 6 | S21: 0 | U21: 1 | W21: 2 | Y21: 3 | AA21: 4 | AC21: 5 | AE21: 6
E23: A-07 | Q23: =IF(ISBLANK(C23),0,Q20) -> 0 | U23: F-07 | AG23: =IF(ISBLANK(S23),0,AG20) -> 0
E25: A-08 | Q25: =IF(ISBLANK(C25),0,Q20) -> 0 | U25: F-08 | AG25: =IF(ISBLANK(S25),0,AG20) -> 0
E27: A-09 | Q27: =IF(ISBLANK(C27),0,Q20) -> 0 | U27: F-09 | AG27: =IF(ISBLANK(S27),0,AG20) -> 0
E29: A-10 | Q29: =IF(ISBLANK(C29),0,Q20) -> 0 | U29: F-10 | AG29: =IF(ISBLANK(S29),0,AG20) -> 0
B32: A-11 | R32: F-11
Q33: =IF(ISBLANK(O33),IF(ISBLANK(M33),IF(ISBLANK(K33),IF(ISBLANK(I33),IF(ISBLANK(G33),IF(ISBLANK(E33),0,1),2),3),4),5),6) -> 0 | AG33: =IF(ISBLANK(AE33),IF(ISBLANK(AC33),IF(ISBLANK(AA33),IF(ISBLANK(Y33),IF(ISBLANK(W33),IF(ISBLANK(U33),0,1),2),3),4),5),6) -> 0
C34: 0 | E34: 1 | G34: 2 | I34: 3 | K34: 4 | M34: 5 | O34: 6 | S34: 0 | U34: 1 | W34: 2 | Y34: 3 | AA34: 4 | AC34: 5 | AE34: 6
E36: A-12 | Q36: =IF(ISBLANK(C36),0,Q33) -> 0 | U36: F-12 | AG36: =IF(ISBLANK(S36),0,AG33) -> 0
E38: A-13 | Q38: =IF(ISBLANK(C38),0,Q33) -> 0 | U38: F-13 | AG38: =IF(ISBLANK(S38),0,AG33) -> 0
E40: A-14 | Q40: =IF(ISBLANK(C40),0,Q33) -> 0 | U40: F-14 | AG40: =IF(ISBLANK(S40),0,AG33) -> 0
E42: A-15 | Q42: =IF(ISBLANK(C42),0,Q33) -> 0 | U42: F-15 | AG42: =IF(ISBLANK(S42),0,AG33) -> 0
B44: A-16 | R44: F-16
Q45: =IF(ISBLANK(O45),IF(ISBLANK(M45),IF(ISBLANK(K45),IF(ISBLANK(I45),IF(ISBLANK(G45),IF(ISBLANK(E45),0,1),2),3),4),5),6) -> 0 | AG45: =IF(ISBLANK(AE45),IF(ISBLANK(AC45),IF(ISBLANK(AA45),IF(ISBLANK(Y45),IF(ISBLANK(W45),IF(ISBLANK(U45),0,1),2),3),4),5),6) -> 0
C46: 0 | E46: 1 | G46: 2 | I46: 3 | K46: 4 | M46: 5 | O46: 6 | S46: 0 | U46: 1 | W46: 2 | Y46: 3 | AA46: 4 | AC46: 5 | AE46: 6
B49: A-17 | R49: F-17
Q50: =IF(ISBLANK(O50),IF(ISBLANK(M50),IF(ISBLANK(K50),IF(ISBLANK(I50),IF(ISBLANK(G50),IF(ISBLANK(E50),0,1),2),3),4),5),6) -> 0 | AG50: =IF(ISBLANK(AE50),IF(ISBLANK(AC50),IF(ISBLANK(AA50),IF(ISBLANK(Y50),IF(ISBLANK(W50),IF(ISBLANK(U50),0,1),2),3),4),5),6) -> 0
C51: 0 | E51: 1 | G51: 2 | I51: 3 | K51: 4 | M51: 5 | O51: 6 | S51: 0 | U51: 1 | W51: 2 | Y51: 3 | AA51: 4 | AC51: 5 | AE51: 6
B53: A-18 | R53: F-18
Q54: =IF(ISBLANK(O54),IF(ISBLANK(M54),IF(ISBLANK(K54),IF(ISBLANK(I54),IF(ISBLANK(G54),IF(ISBLANK(E54),0,1),2),3),4),5),6) -> 0 | AG54: =IF(ISBLANK(AE54),IF(ISBLANK(AC54),IF(ISBLANK(AA54),IF(ISBLANK(Y54),IF(ISBLANK(W54),IF(ISBLANK(U54),0,1),2),3),4),5),6) -> 0
C55: 0 | E55: 1 | G55: 2 | I55: 3 | K55: 4 | M55: 5 | O55: 6 | S55: 0 | U55: 1 | W55: 2 | Y55: 3 | AA55: 4 | AC55: 5 | AE55: 6
B57: A-19 | R57: F-19
Q58: =IF(ISBLANK(O58),IF(ISBLANK(M58),IF(ISBLANK(K58),IF(ISBLANK(I58),IF(ISBLANK(G58),IF(ISBLANK(E58),0,1),2),3),4),5),6) -> 0 | AG58: =IF(ISBLANK(AE58),IF(ISBLANK(AC58),IF(ISBLANK(AA58),IF(ISBLANK(Y58),IF(ISBLANK(W58),IF(ISBLANK(U58),0,1),2),3),4),5),6) -> 0
C59: 0 | E59: 1 | G59: 2 | I59: 3 | K59: 4 | M59: 5 | O59: 6 | S59: 0 | U59: 1 | W59: 2 | Y59: 3 | AA59: 4 | AC59: 5 | AE59: 6
B61: A-20
Q62: =IF(ISBLANK(O62),IF(ISBLANK(M62),IF(ISBLANK(K62),IF(ISBLANK(I62),IF(ISBLANK(G62),IF(ISBLANK(E62),0,1),2),3),4),5),6) -> 0 | AG62: =IF(ISBLANK(AE62),IF(ISBLANK(AC62),IF(ISBLANK(AA62),IF(ISBLANK(Y62),IF(ISBLANK(W62),IF(ISBLANK(U62),0,1),2),3),4),5),6) -> 0
C63: 0 | E63: 1 | G63: 2 | I63: 3 | K63: 4 | M63: 5 | O63: 6
B66: SEC-A4
...

Sheet object_7
B1: Date
B3: Name: | R3: Object#: | S3: 7
B5: BLOCK-A | R5: BLOCK-F
B6: A-01 | R6: F-01
Q7: =IF(ISBLANK(O7),IF(ISBLANK(M7),IF(ISBLANK(K7),IF(ISBLANK(I7),IF(ISBLANK(G7),IF(ISBLANK(E7),0,1),2),3),4),5),6) -> 0 | AG7: =IF(ISBLANK(AE7),IF(ISBLANK(AC7),IF(ISBLANK(AA7),IF(ISBLANK(Y7),IF(ISBLANK(W7),IF(ISBLANK(U7),0,1),2),3),4),5),6) -> 0
C8: 0 | E8: 1 | G8: 2 | I8: 3 | K8: 4 | M8: 5 | O8: 6 | S8: 0 | U8: 1 | W8: 2 | Y8: 3 | AA8: 4 | AC8: 5 | AE8: 6
E10: A-02 | Q10: =IF(ISBLANK(C10),0,Q7) -> 0 | U10: F-02 | AG10: =IF(ISBLANK(S10),0,AG7) -> 0
E12: A-03 | Q12: =IF(ISBLANK(C12),0,Q7) -> 0 | U12: F-03 | AG12: =IF(ISBLANK(S12),0,AG7) -> 0
E14: A-04 | Q14: =IF(ISBLANK(C14),0,Q7) -> 0 | U14: F-04 | AG14: =IF(ISBLANK(S14),0,AG7) -> 0
E16: A-05 | Q16: =IF(ISBLANK(C16),0,Q7) -> 0 | U16: F-05 | AG16: =IF(ISBLANK(S16),0,AG7) -> 0
B19: A-06 | R19: F-06
Q20: =IF(ISBLANK(O20),IF(ISBLANK(M20),IF(ISBLANK(K20),IF(ISBLANK(I20),IF(ISBLANK(G20),IF(ISBLANK(E20),0,1),2),3),4),5),6) -> 0 | AG20: =IF(ISBLANK(AE20),IF(ISBLANK(AC20),IF(ISBLANK(AA20),IF(ISBLANK(Y20),IF(ISBLANK(W20),IF(ISBLANK(U20),0,1),2),3),4),5),6) -> 0
C21: 0 | E21: 1 | G21: 2 | I21: 3 | K21: 4 | M21: 5 | O21: 6 | S21: 0 | U21: 1 | W21: 2 | Y21: 3 | AA21: 4 | AC21: 5 | AE21: 6
E23: A-07 | Q23: =IF(ISBLANK(C23),0,Q20) -> 0 | U23: F-07 | AG23: =IF(ISBLANK(S23),0,AG20) -> 0
E25: A-08 | Q25: =IF(ISBLANK(C25),0,Q20) -> 0 | U25: F-08 | AG25: =IF(ISBLANK(S25),0,AG20) -> 0
E27: A-09 | Q27: =IF(ISBLANK(C27),0,Q20) -> 0 | U27: F-09 | AG27: =IF(ISBLANK(S27),0,AG20) -> 0
E29: A-10 | Q29: =IF(ISBLANK(C29),0,Q20) -> 0 | U29: F-10 | AG29: =IF(ISBLANK(S29),0,AG20) -> 0
B32: A-11 | R32: F-11
Q33: =IF(ISBLANK(O33),IF(ISBLANK(M33),IF(ISBLANK(K33),IF(ISBLANK(I33),IF(ISBLANK(G33),IF(ISBLANK(E33),0,1),2),3),4),5),6) -> 0 | AG33: =IF(ISBLANK(AE33),IF(ISBLANK(AC33),IF(ISBLANK(AA33),IF(ISBLANK(Y33),IF(ISBLANK(W33),IF(ISBLANK(U33),0,1),2),3),4),5),6) -> 0
C34: 0 | E34: 1 | G34: 2 | I34: 3 | K34: 4 | M34: 5 | O34: 6 | S34: 0 | U34: 1 | W34: 2 | Y34: 3 | AA34: 4 | AC34: 5 | AE34: 6
E36: A-12 | Q36: =IF(ISBLANK(C36),0,Q33) -> 0 | U36: F-12 | AG36: =IF(ISBLANK(S36),0,AG33) -> 0
E38: A-13 | Q38: =IF(ISBLANK(C38),0,Q33) -> 0 | U38: F-13 | AG38: =IF(ISBLANK(S38),0,AG33) -> 0
E40: A-14 | Q40: =IF(ISBLANK(C40),0,Q33) -> 0 | U40: F-14 | AG40: =IF(ISBLANK(S40),0,AG33) -> 0
E42: A-15 | Q42: =IF(ISBLANK(C42),0,Q33) -> 0 | U42: F-15 | AG42: =IF(ISBLANK(S42),0,AG33) -> 0
B44: A-16 | R44: F-16
Q45: =IF(ISBLANK(O45),IF(ISBLANK(M45),IF(ISBLANK(K45),IF(ISBLANK(I45),IF(ISBLANK(G45),IF(ISBLANK(E45),0,1),2),3),4),5),6) -> 0 | AG45: =IF(ISBLANK(AE45),IF(ISBLANK(AC45),IF(ISBLANK(AA45),IF(ISBLANK(Y45),IF(ISBLANK(W45),IF(ISBLANK(U45),0,1),2),3),4),5),6) -> 0
C46: 0 | E46: 1 | G46: 2 | I46: 3 | K46: 4 | M46: 5 | O46: 6 | S46: 0 | U46: 1 | W46: 2 | Y46: 3 | AA46: 4 | AC46: 5 | AE46: 6
B49: A-17 | R49: F-17
Q50: =IF(ISBLANK(O50),IF(ISBLANK(M50),IF(ISBLANK(K50),IF(ISBLANK(I50),IF(ISBLANK(G50),IF(ISBLANK(E50),0,1),2),3),4),5),6) -> 0 | AG50: =IF(ISBLANK(AE50),IF(ISBLANK(AC50),IF(ISBLANK(AA50),IF(ISBLANK(Y50),IF(ISBLANK(W50),IF(ISBLANK(U50),0,1),2),3),4),5),6) -> 0
C51: 0 | E51: 1 | G51: 2 | I51: 3 | K51: 4 | M51: 5 | O51: 6 | S51: 0 | U51: 1 | W51: 2 | Y51: 3 | AA51: 4 | AC51: 5 | AE51: 6
B53: A-18 | R53: F-18
Q54: =IF(ISBLANK(O54),IF(ISBLANK(M54),IF(ISBLANK(K54),IF(ISBLANK(I54),IF(ISBLANK(G54),IF(ISBLANK(E54),0,1),2),3),4),5),6) -> 0 | AG54: =IF(ISBLANK(AE54),IF(ISBLANK(AC54),IF(ISBLANK(AA54),IF(ISBLANK(Y54),IF(ISBLANK(W54),IF(ISBLANK(U54),0,1),2),3),4),5),6) -> 0
C55: 0 | E55: 1 | G55: 2 | I55: 3 | K55: 4 | M55: 5 | O55: 6 | S55: 0 | U55: 1 | W55: 2 | Y55: 3 | AA55: 4 | AC55: 5 | AE55: 6
B57: A-19 | R57: F-19
Q58: =IF(ISBLANK(O58),IF(ISBLANK(M58),IF(ISBLANK(K58),IF(ISBLANK(I58),IF(ISBLANK(G58),IF(ISBLANK(E58),0,1),2),3),4),5),6) -> 0 | AG58: =IF(ISBLANK(AE58),IF(ISBLANK(AC58),IF(ISBLANK(AA58),IF(ISBLANK(Y58),IF(ISBLANK(W58),IF(ISBLANK(U58),0,1),2),3),4),5),6) -> 0
C59: 0 | E59: 1 | G59: 2 | I59: 3 | K59: 4 | M59: 5 | O59: 6 | S59: 0 | U59: 1 | W59: 2 | Y59: 3 | AA59: 4 | AC59: 5 | AE59: 6
B61: A-20
Q62: =IF(ISBLANK(O62),IF(ISBLANK(M62),IF(ISBLANK(K62),IF(ISBLANK(I62),IF(ISBLANK(G62),IF(ISBLANK(E62),0,1),2),3),4),5),6) -> 0 | AG62: =IF(ISBLANK(AE62),IF(ISBLANK(AC62),IF(ISBLANK(AA62),IF(ISBLANK(Y62),IF(ISBLANK(W62),IF(ISBLANK(U62),0,1),2),3),4),5),6) -> 0
C63: 0 | E63: 1 | G63: 2 | I63: 3 | K63: 4 | M63: 5 | O63: 6
B66: SEC-A4
...

Sheet object_8
B1: Date
B3: Name: | R3: Object#: | S3: 8
B5: BLOCK-A | R5: BLOCK-F
B6: A-01 | R6: F-01
Q7: =IF(ISBLANK(O7),IF(ISBLANK(M7),IF(ISBLANK(K7),IF(ISBLANK(I7),IF(ISBLANK(G7),IF(ISBLANK(E7),0,1),2),3),4),5),6) -> 0 | AG7: =IF(ISBLANK(AE7),IF(ISBLANK(AC7),IF(ISBLANK(AA7),IF(ISBLANK(Y7),IF(ISBLANK(W7),IF(ISBLANK(U7),0,1),2),3),4),5),6) -> 0
C8: 0 | E8: 1 | G8: 2 | I8: 3 | K8: 4 | M8: 5 | O8: 6 | S8: 0 | U8: 1 | W8: 2 | Y8: 3 | AA8: 4 | AC8: 5 | AE8: 6
E10: A-02 | Q10: =IF(ISBLANK(C10),0,Q7) -> 0 | U10: F-02 | AG10: =IF(ISBLANK(S10),0,AG7) -> 0
E12: A-03 | Q12: =IF(ISBLANK(C12),0,Q7) -> 0 | U12: F-03 | AG12: =IF(ISBLANK(S12),0,AG7) -> 0
E14: A-04 | Q14: =IF(ISBLANK(C14),0,Q7) -> 0 | U14: F-04 | AG14: =IF(ISBLANK(S14),0,AG7) -> 0
E16: A-05 | Q16: =IF(ISBLANK(C16),0,Q7) -> 0 | U16: F-05 | AG16: =IF(ISBLANK(S16),0,AG7) -> 0
B19: A-06 | R19: F-06
Q20: =IF(ISBLANK(O20),IF(ISBLANK(M20),IF(ISBLANK(K20),IF(ISBLANK(I20),IF(ISBLANK(G20),IF(ISBLANK(E20),0,1),2),3),4),5),6) -> 0 | AG20: =IF(ISBLANK(AE20),IF(ISBLANK(AC20),IF(ISBLANK(AA20),IF(ISBLANK(Y20),IF(ISBLANK(W20),IF(ISBLANK(U20),0,1),2),3),4),5),6) -> 0
C21: 0 | E21: 1 | G21: 2 | I21: 3 | K21: 4 | M21: 5 | O21: 6 | S21: 0 | U21: 1 | W21: 2 | Y21: 3 | AA21: 4 | AC21: 5 | AE21: 6
E23: A-07 | Q23: =IF(ISBLANK(C23),0,Q20) -> 0 | U23: F-07 | AG23: =IF(ISBLANK(S23),0,AG20) -> 0
E25: A-08 | Q25: =IF(ISBLANK(C25),0,Q20) -> 0 | U25: F-08 | AG25: =IF(ISBLANK(S25),0,AG20) -> 0
E27: A-09 | Q27: =IF(ISBLANK(C27),0,Q20) -> 0 | U27: F-09 | AG27: =IF(ISBLANK(S27),0,AG20) -> 0
E29: A-10 | Q29: =IF(ISBLANK(C29),0,Q20) -> 0 | U29: F-10 | AG29: =IF(ISBLANK(S29),0,AG20) -> 0
B32: A-11 | R32: F-11
Q33: =IF(ISBLANK(O33),IF(ISBLANK(M33),IF(ISBLANK(K33),IF(ISBLANK(I33),IF(ISBLANK(G33),IF(ISBLANK(E33),0,1),2),3),4),5),6) -> 0 | AG33: =IF(ISBLANK(AE33),IF(ISBLANK(AC33),IF(ISBLANK(AA33),IF(ISBLANK(Y33),IF(ISBLANK(W33),IF(ISBLANK(U33),0,1),2),3),4),5),6) -> 0
C34: 0 | E34: 1 | G34: 2 | I34: 3 | K34: 4 | M34: 5 | O34: 6 | S34: 0 | U34: 1 | W34: 2 | Y34: 3 | AA34: 4 | AC34: 5 | AE34: 6
E36: A-12 | Q36: =IF(ISBLANK(C36),0,Q33) -> 0 | U36: F-12 | AG36: =IF(ISBLANK(S36),0,AG33) -> 0
E38: A-13 | Q38: =IF(ISBLANK(C38),0,Q33) -> 0 | U38: F-13 | AG38: =IF(ISBLANK(S38),0,AG33) -> 0
E40: A-14 | Q40: =IF(ISBLANK(C40),0,Q33) -> 0 | U40: F-14 | AG40: =IF(ISBLANK(S40),0,AG33) -> 0
E42: A-15 | Q42: =IF(ISBLANK(C42),0,Q33) -> 0 | U42: F-15 | AG42: =IF(ISBLANK(S42),0,AG33) -> 0
B44: A-16 | R44: F-16
Q45: =IF(ISBLANK(O45),IF(ISBLANK(M45),IF(ISBLANK(K45),IF(ISBLANK(I45),IF(ISBLANK(G45),IF(ISBLANK(E45),0,1),2),3),4),5),6) -> 0 | AG45: =IF(ISBLANK(AE45),IF(ISBLANK(AC45),IF(ISBLANK(AA45),IF(ISBLANK(Y45),IF(ISBLANK(W45),IF(ISBLANK(U45),0,1),2),3),4),5),6) -> 0
C46: 0 | E46: 1 | G46: 2 | I46: 3 | K46: 4 | M46: 5 | O46: 6 | S46: 0 | U46: 1 | W46: 2 | Y46: 3 | AA46: 4 | AC46: 5 | AE46: 6
B49: A-17 | R49: F-17
Q50: =IF(ISBLANK(O50),IF(ISBLANK(M50),IF(ISBLANK(K50),IF(ISBLANK(I50),IF(ISBLANK(G50),IF(ISBLANK(E50),0,1),2),3),4),5),6) -> 0 | AG50: =IF(ISBLANK(AE50),IF(ISBLANK(AC50),IF(ISBLANK(AA50),IF(ISBLANK(Y50),IF(ISBLANK(W50),IF(ISBLANK(U50),0,1),2),3),4),5),6) -> 0
C51: 0 | E51: 1 | G51: 2 | I51: 3 | K51: 4 | M51: 5 | O51: 6 | S51: 0 | U51: 1 | W51: 2 | Y51: 3 | AA51: 4 | AC51: 5 | AE51: 6
B53: A-18 | R53: F-18
Q54: =IF(ISBLANK(O54),IF(ISBLANK(M54),IF(ISBLANK(K54),IF(ISBLANK(I54),IF(ISBLANK(G54),IF(ISBLANK(E54),0,1),2),3),4),5),6) -> 0 | AG54: =IF(ISBLANK(AE54),IF(ISBLANK(AC54),IF(ISBLANK(AA54),IF(ISBLANK(Y54),IF(ISBLANK(W54),IF(ISBLANK(U54),0,1),2),3),4),5),6) -> 0
C55: 0 | E55: 1 | G55: 2 | I55: 3 | K55: 4 | M55: 5 | O55: 6 | S55: 0 | U55: 1 | W55: 2 | Y55: 3 | AA55: 4 | AC55: 5 | AE55: 6
B57: A-19 | R57: F-19
Q58: =IF(ISBLANK(O58),IF(ISBLANK(M58),IF(ISBLANK(K58),IF(ISBLANK(I58),IF(ISBLANK(G58),IF(ISBLANK(E58),0,1),2),3),4),5),6) -> 0 | AG58: =IF(ISBLANK(AE58),IF(ISBLANK(AC58),IF(ISBLANK(AA58),IF(ISBLANK(Y58),IF(ISBLANK(W58),IF(ISBLANK(U58),0,1),2),3),4),5),6) -> 0
C59: 0 | E59: 1 | G59: 2 | I59: 3 | K59: 4 | M59: 5 | O59: 6 | S59: 0 | U59: 1 | W59: 2 | Y59: 3 | AA59: 4 | AC59: 5 | AE59: 6
B61: A-20
Q62: =IF(ISBLANK(O62),IF(ISBLANK(M62),IF(ISBLANK(K62),IF(ISBLANK(I62),IF(ISBLANK(G62),IF(ISBLANK(E62),0,1),2),3),4),5),6) -> 0 | AG62: =IF(ISBLANK(AE62),IF(ISBLANK(AC62),IF(ISBLANK(AA62),IF(ISBLANK(Y62),IF(ISBLANK(W62),IF(ISBLANK(U62),0,1),2),3),4),5),6) -> 0
C63: 0 | E63: 1 | G63: 2 | I63: 3 | K63: 4 | M63: 5 | O63: 6
B66: SEC-A4
...

Sheet object_9
B1: Date
B3: Name: | R3: Object#: | S3: 9
B5: BLOCK-A | R5: BLOCK-F
B6: A-01 | R6: F-01
Q7: =IF(ISBLANK(O7),IF(ISBLANK(M7),IF(ISBLANK(K7),IF(ISBLANK(I7),IF(ISBLANK(G7),IF(ISBLANK(E7),0,1),2),3),4),5),6) -> 0 | AG7: =IF(ISBLANK(AE7),IF(ISBLANK(AC7),IF(ISBLANK(AA7),IF(ISBLANK(Y7),IF(ISBLANK(W7),IF(ISBLANK(U7),0,1),2),3),4),5),6) -> 0
C8: 0 | E8: 1 | G8: 2 | I8: 3 | K8: 4 | M8: 5 | O8: 6 | S8: 0 | U8: 1 | W8: 2 | Y8: 3 | AA8: 4 | AC8: 5 | AE8: 6
E10: A-02 | Q10: =IF(ISBLANK(C10),0,Q7) -> 0 | U10: F-02 | AG10: =IF(ISBLANK(S10),0,AG7) -> 0
E12: A-03 | Q12: =IF(ISBLANK(C12),0,Q7) -> 0 | U12: F-03 | AG12: =IF(ISBLANK(S12),0,AG7) -> 0
E14: A-04 | Q14: =IF(ISBLANK(C14),0,Q7) -> 0 | U14: F-04 | AG14: =IF(ISBLANK(S14),0,AG7) -> 0
E16: A-05 | Q16: =IF(ISBLANK(C16),0,Q7) -> 0 | U16: F-05 | AG16: =IF(ISBLANK(S16),0,AG7) -> 0
B19: A-06 | R19: F-06
Q20: =IF(ISBLANK(O20),IF(ISBLANK(M20),IF(ISBLANK(K20),IF(ISBLANK(I20),IF(ISBLANK(G20),IF(ISBLANK(E20),0,1),2),3),4),5),6) -> 0 | AG20: =IF(ISBLANK(AE20),IF(ISBLANK(AC20),IF(ISBLANK(AA20),IF(ISBLANK(Y20),IF(ISBLANK(W20),IF(ISBLANK(U20),0,1),2),3),4),5),6) -> 0
C21: 0 | E21: 1 | G21: 2 | I21: 3 | K21: 4 | M21: 5 | O21: 6 | S21: 0 | U21: 1 | W21: 2 | Y21: 3 | AA21: 4 | AC21: 5 | AE21: 6
E23: A-07 | Q23: =IF(ISBLANK(C23),0,Q20) -> 0 | U23: F-07 | AG23: =IF(ISBLANK(S23),0,AG20) -> 0
E25: A-08 | Q25: =IF(ISBLANK(C25),0,Q20) -> 0 | U25: F-08 | AG25: =IF(ISBLANK(S25),0,AG20) -> 0
E27: A-09 | Q27: =IF(ISBLANK(C27),0,Q20) -> 0 | U27: F-09 | AG27: =IF(ISBLANK(S27),0,AG20) -> 0
E29: A-10 | Q29: =IF(ISBLANK(C29),0,Q20) -> 0 | U29: F-10 | AG29: =IF(ISBLANK(S29),0,AG20) -> 0
B32: A-11 | R32: F-11
Q33: =IF(ISBLANK(O33),IF(ISBLANK(M33),IF(ISBLANK(K33),IF(ISBLANK(I33),IF(ISBLANK(G33),IF(ISBLANK(E33),0,1),2),3),4),5),6) -> 0 | AG33: =IF(ISBLANK(AE33),IF(ISBLANK(AC33),IF(ISBLANK(AA33),IF(ISBLANK(Y33),IF(ISBLANK(W33),IF(ISBLANK(U33),0,1),2),3),4),5),6) -> 0
C34: 0 | E34: 1 | G34: 2 | I34: 3 | K34: 4 | M34: 5 | O34: 6 | S34: 0 | U34: 1 | W34: 2 | Y34: 3 | AA34: 4 | AC34: 5 | AE34: 6
E36: A-12 | Q36: =IF(ISBLANK(C36),0,Q33) -> 0 | U36: F-12 | AG36: =IF(ISBLANK(S36),0,AG33) -> 0
E38: A-13 | Q38: =IF(ISBLANK(C38),0,Q33) -> 0 | U38: F-13 | AG38: =IF(ISBLANK(S38),0,AG33) -> 0
E40: A-14 | Q40: =IF(ISBLANK(C40),0,Q33) -> 0 | U40: F-14 | AG40: =IF(ISBLANK(S40),0,AG33) -> 0
E42: A-15 | Q42: =IF(ISBLANK(C42),0,Q33) -> 0 | U42: F-15 | AG42: =IF(ISBLANK(S42),0,AG33) -> 0
B44: A-16 | R44: F-16
Q45: =IF(ISBLANK(O45),IF(ISBLANK(M45),IF(ISBLANK(K45),IF(ISBLANK(I45),IF(ISBLANK(G45),IF(ISBLANK(E45),0,1),2),3),4),5),6) -> 0 | AG45: =IF(ISBLANK(AE45),IF(ISBLANK(AC45),IF(ISBLANK(AA45),IF(ISBLANK(Y45),IF(ISBLANK(W45),IF(ISBLANK(U45),0,1),2),3),4),5),6) -> 0
C46: 0 | E46: 1 | G46: 2 | I46: 3 | K46: 4 | M46: 5 | O46: 6 | S46: 0 | U46: 1 | W46: 2 | Y46: 3 | AA46: 4 | AC46: 5 | AE46: 6
B49: A-17 | R49: F-17
Q50: =IF(ISBLANK(O50),IF(ISBLANK(M50),IF(ISBLANK(K50),IF(ISBLANK(I50),IF(ISBLANK(G50),IF(ISBLANK(E50),0,1),2),3),4),5),6) -> 0 | AG50: =IF(ISBLANK(AE50),IF(ISBLANK(AC50),IF(ISBLANK(AA50),IF(ISBLANK(Y50),IF(ISBLANK(W50),IF(ISBLANK(U50),0,1),2),3),4),5),6) -> 0
C51: 0 | E51: 1 | G51: 2 | I51: 3 | K51: 4 | M51: 5 | O51: 6 | S51: 0 | U51: 1 | W51: 2 | Y51: 3 | AA51: 4 | AC51: 5 | AE51: 6
B53: A-18 | R53: F-18
Q54: =IF(ISBLANK(O54),IF(ISBLANK(M54),IF(ISBLANK(K54),IF(ISBLANK(I54),IF(ISBLANK(G54),IF(ISBLANK(E54),0,1),2),3),4),5),6) -> 0 | AG54: =IF(ISBLANK(AE54),IF(ISBLANK(AC54),IF(ISBLANK(AA54),IF(ISBLANK(Y54),IF(ISBLANK(W54),IF(ISBLANK(U54),0,1),2),3),4),5),6) -> 0
C55: 0 | E55: 1 | G55: 2 | I55: 3 | K55: 4 | M55: 5 | O55: 6 | S55: 0 | U55: 1 | W55: 2 | Y55: 3 | AA55: 4 | AC55: 5 | AE55: 6
B57: A-19 | R57: F-19
Q58: =IF(ISBLANK(O58),IF(ISBLANK(M58),IF(ISBLANK(K58),IF(ISBLANK(I58),IF(ISBLANK(G58),IF(ISBLANK(E58),0,1),2),3),4),5),6) -> 0 | AG58: =IF(ISBLANK(AE58),IF(ISBLANK(AC58),IF(ISBLANK(AA58),IF(ISBLANK(Y58),IF(ISBLANK(W58),IF(ISBLANK(U58),0,1),2),3),4),5),6) -> 0
C59: 0 | E59: 1 | G59: 2 | I59: 3 | K59: 4 | M59: 5 | O59: 6 | S59: 0 | U59: 1 | W59: 2 | Y59: 3 | AA59: 4 | AC59: 5 | AE59: 6
B61: A-20
Q62: =IF(ISBLANK(O62),IF(ISBLANK(M62),IF(ISBLANK(K62),IF(ISBLANK(I62),IF(ISBLANK(G62),IF(ISBLANK(E62),0,1),2),3),4),5),6) -> 0 | AG62: =IF(ISBLANK(AE62),IF(ISBLANK(AC62),IF(ISBLANK(AA62),IF(ISBLANK(Y62),IF(ISBLANK(W62),IF(ISBLANK(U62),0,1),2),3),4),5),6) -> 0
C63: 0 | E63: 1 | G63: 2 | I63: 3 | K63: 4 | M63: 5 | O63: 6
B66: SEC-A4
...

Sheet object_10
B1: Date
B3: Name: | R3: Object#: | S3: 10
B5: BLOCK-A | R5: BLOCK-F
B6: A-01 | R6: F-01
Q7: =IF(ISBLANK(O7),IF(ISBLANK(M7),IF(ISBLANK(K7),IF(ISBLANK(I7),IF(ISBLANK(G7),IF(ISBLANK(E7),0,1),2),3),4),5),6) -> 0 | AG7: =IF(ISBLANK(AE7),IF(ISBLANK(AC7),IF(ISBLANK(AA7),IF(ISBLANK(Y7),IF(ISBLANK(W7),IF(ISBLANK(U7),0,1),2),3),4),5),6) -> 0
C8: 0 | E8: 1 | G8: 2 | I8: 3 | K8: 4 | M8: 5 | O8: 6 | S8: 0 | U8: 1 | W8: 2 | Y8: 3 | AA8: 4 | AC8: 5 | AE8: 6
E10: A-02 | Q10: =IF(ISBLANK(C10),0,Q7) -> 0 | U10: F-02 | AG10: =IF(ISBLANK(S10),0,AG7) -> 0
E12: A-03 | Q12: =IF(ISBLANK(C12),0,Q7) -> 0 | U12: F-03 | AG12: =IF(ISBLANK(S12),0,AG7) -> 0
E14: A-04 | Q14: =IF(ISBLANK(C14),0,Q7) -> 0 | U14: F-04 | AG14: =IF(ISBLANK(S14),0,AG7) -> 0
E16: A-05 | Q16: =IF(ISBLANK(C16),0,Q7) -> 0 | U16: F-05 | AG16: =IF(ISBLANK(S16),0,AG7) -> 0
B19: A-06 | R19: F-06
Q20: =IF(ISBLANK(O20),IF(ISBLANK(M20),IF(ISBLANK(K20),IF(ISBLANK(I20),IF(ISBLANK(G20),IF(ISBLANK(E20),0,1),2),3),4),5),6) -> 0 | AG20: =IF(ISBLANK(AE20),IF(ISBLANK(AC20),IF(ISBLANK(AA20),IF(ISBLANK(Y20),IF(ISBLANK(W20),IF(ISBLANK(U20),0,1),2),3),4),5),6) -> 0
C21: 0 | E21: 1 | G21: 2 | I21: 3 | K21: 4 | M21: 5 | O21: 6 | S21: 0 | U21: 1 | W21: 2 | Y21: 3 | AA21: 4 | AC21: 5 | AE21: 6
E23: A-07 | Q23: =IF(ISBLANK(C23),0,Q20) -> 0 | U23: F-07 | AG23: =IF(ISBLANK(S23),0,AG20) -> 0
E25: A-08 | Q25: =IF(ISBLANK(C25),0,Q20) -> 0 | U25: F-08 | AG25: =IF(ISBLANK(S25),0,AG20) -> 0
E27: A-09 | Q27: =IF(ISBLANK(C27),0,Q20) -> 0 | U27: F-09 | AG27: =IF(ISBLANK(S27),0,AG20) -> 0
E29: A-10 | Q29: =IF(ISBLANK(C29),0,Q20) -> 0 | U29: F-10 | AG29: =IF(ISBLANK(S29),0,AG20) -> 0
B32: A-11 | R32: F-11
Q33: =IF(ISBLANK(O33),IF(ISBLANK(M33),IF(ISBLANK(K33),IF(ISBLANK(I33),IF(ISBLANK(G33),IF(ISBLANK(E33),0,1),2),3),4),5),6) -> 0 | AG33: =IF(ISBLANK(AE33),IF(ISBLANK(AC33),IF(ISBLANK(AA33),IF(ISBLANK(Y33),IF(ISBLANK(W33),IF(ISBLANK(U33),0,1),2),3),4),5),6) -> 0
C34: 0 | E34: 1 | G34: 2 | I34: 3 | K34: 4 | M34: 5 | O34: 6 | S34: 0 | U34: 1 | W34: 2 | Y34: 3 | AA34: 4 | AC34: 5 | AE34: 6
E36: A-12 | Q36: =IF(ISBLANK(C36),0,Q33) -> 0 | U36: F-12 | AG36: =IF(ISBLANK(S36),0,AG33) -> 0
E38: A-13 | Q38: =IF(ISBLANK(C38),0,Q33) -> 0 | U38: F-13 | AG38: =IF(ISBLANK(S38),0,AG33) -> 0
E40: A-14 | Q40: =IF(ISBLANK(C40),0,Q33) -> 0 | U40: F-14 | AG40: =IF(ISBLANK(S40),0,AG33) -> 0
E42: A-15 | Q42: =IF(ISBLANK(C42),0,Q33) -> 0 | U42: F-15 | AG42: =IF(ISBLANK(S42),0,AG33) -> 0
B44: A-16 | R44: F-16
Q45: =IF(ISBLANK(O45),IF(ISBLANK(M45),IF(ISBLANK(K45),IF(ISBLANK(I45),IF(ISBLANK(G45),IF(ISBLANK(E45),0,1),2),3),4),5),6) -> 0 | AG45: =IF(ISBLANK(AE45),IF(ISBLANK(AC45),IF(ISBLANK(AA45),IF(ISBLANK(Y45),IF(ISBLANK(W45),IF(ISBLANK(U45),0,1),2),3),4),5),6) -> 0
C46: 0 | E46: 1 | G46: 2 | I46: 3 | K46: 4 | M46: 5 | O46: 6 | S46: 0 | U46: 1 | W46: 2 | Y46: 3 | AA46: 4 | AC46: 5 | AE46: 6
B49: A-17 | R49: F-17
Q50: =IF(ISBLANK(O50),IF(ISBLANK(M50),IF(ISBLANK(K50),IF(ISBLANK(I50),IF(ISBLANK(G50),IF(ISBLANK(E50),0,1),2),3),4),5),6) -> 0 | AG50: =IF(ISBLANK(AE50),IF(ISBLANK(AC50),IF(ISBLANK(AA50),IF(ISBLANK(Y50),IF(ISBLANK(W50),IF(ISBLANK(U50),0,1),2),3),4),5),6) -> 0
C51: 0 | E51: 1 | G51: 2 | I51: 3 | K51: 4 | M51: 5 | O51: 6 | S51: 0 | U51: 1 | W51: 2 | Y51: 3 | AA51: 4 | AC51: 5 | AE51: 6
B53: A-18 | R53: F-18
Q54: =IF(ISBLANK(O54),IF(ISBLANK(M54),IF(ISBLANK(K54),IF(ISBLANK(I54),IF(ISBLANK(G54),IF(ISBLANK(E54),0,1),2),3),4),5),6) -> 0 | AG54: =IF(ISBLANK(AE54),IF(ISBLANK(AC54),IF(ISBLANK(AA54),IF(ISBLANK(Y54),IF(ISBLANK(W54),IF(ISBLANK(U54),0,1),2),3),4),5),6) -> 0
C55: 0 | E55: 1 | G55: 2 | I55: 3 | K55: 4 | M55: 5 | O55: 6 | S55: 0 | U55: 1 | W55: 2 | Y55: 3 | AA55: 4 | AC55: 5 | AE55: 6
B57: A-19 | R57: F-19
Q58: =IF(ISBLANK(O58),IF(ISBLANK(M58),IF(ISBLANK(K58),IF(ISBLANK(I58),IF(ISBLANK(G58),IF(ISBLANK(E58),0,1),2),3),4),5),6) -> 0 | AG58: =IF(ISBLANK(AE58),IF(ISBLANK(AC58),IF(ISBLANK(AA58),IF(ISBLANK(Y58),IF(ISBLANK(W58),IF(ISBLANK(U58),0,1),2),3),4),5),6) -> 0
C59: 0 | E59: 1 | G59: 2 | I59: 3 | K59: 4 | M59: 5 | O59: 6 | S59: 0 | U59: 1 | W59: 2 | Y59: 3 | AA59: 4 | AC59: 5 | AE59: 6
B61: A-20
Q62: =IF(ISBLANK(O62),IF(ISBLANK(M62),IF(ISBLANK(K62),IF(ISBLANK(I62),IF(ISBLANK(G62),IF(ISBLANK(E62),0,1),2),3),4),5),6) -> 0 | AG62: =IF(ISBLANK(AE62),IF(ISBLANK(AC62),IF(ISBLANK(AA62),IF(ISBLANK(Y62),IF(ISBLANK(W62),IF(ISBLANK(U62),0,1),2),3),4),5),6) -> 0
C63: 0 | E63: 1 | G63: 2 | I63: 3 | K63: 4 | M63: 5 | O63: 6
B66: SEC-A4
...

Sheet object_11
B1: Date
B3: Name: | R3: Object#: | S3: 11
B5: BLOCK-A | R5: BLOCK-F
B6: A-01 | R6: F-01
Q7: =IF(ISBLANK(O7),IF(ISBLANK(M7),IF(ISBLANK(K7),IF(ISBLANK(I7),IF(ISBLANK(G7),IF(ISBLANK(E7),0,1),2),3),4),5),6) -> 0 | AG7: =IF(ISBLANK(AE7),IF(ISBLANK(AC7),IF(ISBLANK(AA7),IF(ISBLANK(Y7),IF(ISBLANK(W7),IF(ISBLANK(U7),0,1),2),3),4),5),6) -> 0
C8: 0 | E8: 1 | G8: 2 | I8: 3 | K8: 4 | M8: 5 | O8: 6 | S8: 0 | U8: 1 | W8: 2 | Y8: 3 | AA8: 4 | AC8: 5 | AE8: 6
E10: A-02 | Q10: =IF(ISBLANK(C10),0,Q7) -> 0 | U10: F-02 | AG10: =IF(ISBLANK(S10),0,AG7) -> 0
E12: A-03 | Q12: =IF(ISBLANK(C12),0,Q7) -> 0 | U12: F-03 | AG12: =IF(ISBLANK(S12),0,AG7) -> 0
E14: A-04 | Q14: =IF(ISBLANK(C14),0,Q7) -> 0 | U14: F-04 | AG14: =IF(ISBLANK(S14),0,AG7) -> 0
E16: A-05 | Q16: =IF(ISBLANK(C16),0,Q7) -> 0 | U16: F-05 | AG16: =IF(ISBLANK(S16),0,AG7) -> 0
B19: A-06 | R19: F-06
Q20: =IF(ISBLANK(O20),IF(ISBLANK(M20),IF(ISBLANK(K20),IF(ISBLANK(I20),IF(ISBLANK(G20),IF(ISBLANK(E20),0,1),2),3),4),5),6) -> 0 | AG20: =IF(ISBLANK(AE20),IF(ISBLANK(AC20),IF(ISBLANK(AA20),IF(ISBLANK(Y20),IF(ISBLANK(W20),IF(ISBLANK(U20),0,1),2),3),4),5),6) -> 0
C21: 0 | E21: 1 | G21: 2 | I21: 3 | K21: 4 | M21: 5 | O21: 6 | S21: 0 | U21: 1 | W21: 2 | Y21: 3 | AA21: 4 | AC21: 5 | AE21: 6
E23: A-07 | Q23: =IF(ISBLANK(C23),0,Q20) -> 0 | U23: F-07 | AG23: =IF(ISBLANK(S23),0,AG20) -> 0
E25: A-08 | Q25: =IF(ISBLANK(C25),0,Q20) -> 0 | U25: F-08 | AG25: =IF(ISBLANK(S25),0,AG20) -> 0
E27: A-09 | Q27: =IF(ISBLANK(C27),0,Q20) -> 0 | U27: F-09 | AG27: =IF(ISBLANK(S27),0,AG20) -> 0
E29: A-10 | Q29: =IF(ISBLANK(C29),0,Q20) -> 0 | U29: F-10 | AG29: =IF(ISBLANK(S29),0,AG20) -> 0
B32: A-11 | R32: F-11
Q33: =IF(ISBLANK(O33),IF(ISBLANK(M33),IF(ISBLANK(K33),IF(ISBLANK(I33),IF(ISBLANK(G33),IF(ISBLANK(E33),0,1),2),3),4),5),6) -> 0 | AG33: =IF(ISBLANK(AE33),IF(ISBLANK(AC33),IF(ISBLANK(AA33),IF(ISBLANK(Y33),IF(ISBLANK(W33),IF(ISBLANK(U33),0,1),2),3),4),5),6) -> 0
C34: 0 | E34: 1 | G34: 2 | I34: 3 | K34: 4 | M34: 5 | O34: 6 | S34: 0 | U34: 1 | W34: 2 | Y34: 3 | AA34: 4 | AC34: 5 | AE34: 6
E36: A-12 | Q36: =IF(ISBLANK(C36),0,Q33) -> 0 | U36: F-12 | AG36: =IF(ISBLANK(S36),0,AG33) -> 0
E38: A-13 | Q38: =IF(ISBLANK(C38),0,Q33) -> 0 | U38: F-13 | AG38: =IF(ISBLANK(S38),0,AG33) -> 0
E40: A-14 | Q40: =IF(ISBLANK(C40),0,Q33) -> 0 | U40: F-14 | AG40: =IF(ISBLANK(S40),0,AG33) -> 0
E42: A-15 | Q42: =IF(ISBLANK(C42),0,Q33) -> 0 | U42: F-15 | AG42: =IF(ISBLANK(S42),0,AG33) -> 0
B44: A-16 | R44: F-16
Q45: =IF(ISBLANK(O45),IF(ISBLANK(M45),IF(ISBLANK(K45),IF(ISBLANK(I45),IF(ISBLANK(G45),IF(ISBLANK(E45),0,1),2),3),4),5),6) -> 0 | AG45: =IF(ISBLANK(AE45),IF(ISBLANK(AC45),IF(ISBLANK(AA45),IF(ISBLANK(Y45),IF(ISBLANK(W45),IF(ISBLANK(U45),0,1),2),3),4),5),6) -> 0
C46: 0 | E46: 1 | G46: 2 | I46: 3 | K46: 4 | M46: 5 | O46: 6 | S46: 0 | U46: 1 | W46: 2 | Y46: 3 | AA46: 4 | AC46: 5 | AE46: 6
B49: A-17 | R49: F-17
Q50: =IF(ISBLANK(O50),IF(ISBLANK(M50),IF(ISBLANK(K50),IF(ISBLANK(I50),IF(ISBLANK(G50),IF(ISBLANK(E50),0,1),2),3),4),5),6) -> 0 | AG50: =IF(ISBLANK(AE50),IF(ISBLANK(AC50),IF(ISBLANK(AA50),IF(ISBLANK(Y50),IF(ISBLANK(W50),IF(ISBLANK(U50),0,1),2),3),4),5),6) -> 0
C51: 0 | E51: 1 | G51: 2 | I51: 3 | K51: 4 | M51: 5 | O51: 6 | S51: 0 | U51: 1 | W51: 2 | Y51: 3 | AA51: 4 | AC51: 5 | AE51: 6
B53: A-18 | R53: F-18
Q54: =IF(ISBLANK(O54),IF(ISBLANK(M54),IF(ISBLANK(K54),IF(ISBLANK(I54),IF(ISBLANK(G54),IF(ISBLANK(E54),0,1),2),3),4),5),6) -> 0 | AG54: =IF(ISBLANK(AE54),IF(ISBLANK(AC54),IF(ISBLANK(AA54),IF(ISBLANK(Y54),IF(ISBLANK(W54),IF(ISBLANK(U54),0,1),2),3),4),5),6) -> 0
C55: 0 | E55: 1 | G55: 2 | I55: 3 | K55: 4 | M55: 5 | O55: 6 | S55: 0 | U55: 1 | W55: 2 | Y55: 3 | AA55: 4 | AC55: 5 | AE55: 6
B57: A-19 | R57: F-19
Q58: =IF(ISBLANK(O58),IF(ISBLANK(M58),IF(ISBLANK(K58),IF(ISBLANK(I58),IF(ISBLANK(G58),IF(ISBLANK(E58),0,1),2),3),4),5),6) -> 0 | AG58: =IF(ISBLANK(AE58),IF(ISBLANK(AC58),IF(ISBLANK(AA58),IF(ISBLANK(Y58),IF(ISBLANK(W58),IF(ISBLANK(U58),0,1),2),3),4),5),6) -> 0
C59: 0 | E59: 1 | G59: 2 | I59: 3 | K59: 4 | M59: 5 | O59: 6 | S59: 0 | U59: 1 | W59: 2 | Y59: 3 | AA59: 4 | AC59: 5 | AE59: 6
B61: A-20
Q62: =IF(ISBLANK(O62),IF(ISBLANK(M62),IF(ISBLANK(K62),IF(ISBLANK(I62),IF(ISBLANK(G62),IF(ISBLANK(E62),0,1),2),3),4),5),6) -> 0 | AG62: =IF(ISBLANK(AE62),IF(ISBLANK(AC62),IF(ISBLANK(AA62),IF(ISBLANK(Y62),IF(ISBLANK(W62),IF(ISBLANK(U62),0,1),2),3),4),5),6) -> 0
C63: 0 | E63: 1 | G63: 2 | I63: 3 | K63: 4 | M63: 5 | O63: 6
B66: SEC-A4
...

Sheet object_12
B1: Date
B3: Name: | R3: Object#: | S3: 12
B5: BLOCK-A | R5: BLOCK-F
B6: A-01 | R6: F-01
Q7: =IF(ISBLANK(O7),IF(ISBLANK(M7),IF(ISBLANK(K7),IF(ISBLANK(I7),IF(ISBLANK(G7),IF(ISBLANK(E7),0,1),2),3),4),5),6) -> 0 | AG7: =IF(ISBLANK(AE7),IF(ISBLANK(AC7),IF(ISBLANK(AA7),IF(ISBLANK(Y7),IF(ISBLANK(W7),IF(ISBLANK(U7),0,1),2),3),4),5),6) -> 0
C8: 0 | E8: 1 | G8: 2 | I8: 3 | K8: 4 | M8: 5 | O8: 6 | S8: 0 | U8: 1 | W8: 2 | Y8: 3 | AA8: 4 | AC8: 5 | AE8: 6
E10: A-02 | Q10: =IF(ISBLANK(C10),0,Q7) -> 0 | U10: F-02 | AG10: =IF(ISBLANK(S10),0,AG7) -> 0
E12: A-03 | Q12: =IF(ISBLANK(C12),0,Q7) -> 0 | U12: F-03 | AG12: =IF(ISBLANK(S12),0,AG7) -> 0
E14: A-04 | Q14: =IF(ISBLANK(C14),0,Q7) -> 0 | U14: F-04 | AG14: =IF(ISBLANK(S14),0,AG7) -> 0
E16: A-05 | Q16: =IF(ISBLANK(C16),0,Q7) -> 0 | U16: F-05 | AG16: =IF(ISBLANK(S16),0,AG7) -> 0
B19: A-06 | R19: F-06
Q20: =IF(ISBLANK(O20),IF(ISBLANK(M20),IF(ISBLANK(K20),IF(ISBLANK(I20),IF(ISBLANK(G20),IF(ISBLANK(E20),0,1),2),3),4),5),6) -> 0 | AG20: =IF(ISBLANK(AE20),IF(ISBLANK(AC20),IF(ISBLANK(AA20),IF(ISBLANK(Y20),IF(ISBLANK(W20),IF(ISBLANK(U20),0,1),2),3),4),5),6) -> 0
C21: 0 | E21: 1 | G21: 2 | I21: 3 | K21: 4 | M21: 5 | O21: 6 | S21: 0 | U21: 1 | W21: 2 | Y21: 3 | AA21: 4 | AC21: 5 | AE21: 6
E23: A-07 | Q23: =IF(ISBLANK(C23),0,Q20) -> 0 | U23: F-07 | AG23: =IF(ISBLANK(S23),0,AG20) -> 0
E25: A-08 | Q25: =IF(ISBLANK(C25),0,Q20) -> 0 | U25: F-08 | AG25: =IF(ISBLANK(S25),0,AG20) -> 0
E27: A-09 | Q27: =IF(ISBLANK(C27),0,Q20) -> 0 | U27: F-09 | AG27: =IF(ISBLANK(S27),0,AG20) -> 0
E29: A-10 | Q29: =IF(ISBLANK(C29),0,Q20) -> 0 | U29: F-10 | AG29: =IF(ISBLANK(S29),0,AG20) -> 0
B32: A-11 | R32: F-11
Q33: =IF(ISBLANK(O33),IF(ISBLANK(M33),IF(ISBLANK(K33),IF(ISBLANK(I33),IF(ISBLANK(G33),IF(ISBLANK(E33),0,1),2),3),4),5),6) -> 0 | AG33: =IF(ISBLANK(AE33),IF(ISBLANK(AC33),IF(ISBLANK(AA33),IF(ISBLANK(Y33),IF(ISBLANK(W33),IF(ISBLANK(U33),0,1),2),3),4),5),6) -> 0
C34: 0 | E34: 1 | G34: 2 | I34: 3 | K34: 4 | M34: 5 | O34: 6 | S34: 0 | U34: 1 | W34: 2 | Y34: 3 | AA34: 4 | AC34: 5 | AE34: 6
E36: A-12 | Q36: =IF(ISBLANK(C36),0,Q33) -> 0 | U36: F-12 | AG36: =IF(ISBLANK(S36),0,AG33) -> 0
E38: A-13 | Q38: =IF(ISBLANK(C38),0,Q33) -> 0 | U38: F-13 | AG38: =IF(ISBLANK(S38),0,AG33) -> 0
E40: A-14 | Q40: =IF(ISBLANK(C40),0,Q33) -> 0 | U40: F-14 | AG40: =IF(ISBLANK(S40),0,AG33) -> 0
E42: A-15 | Q42: =IF(ISBLANK(C42),0,Q33) -> 0 | U42: F-15 | AG42: =IF(ISBLANK(S42),0,AG33) -> 0
B44: A-16 | R44: F-16
Q45: =IF(ISBLANK(O45),IF(ISBLANK(M45),IF(ISBLANK(K45),IF(ISBLANK(I45),IF(ISBLANK(G45),IF(ISBLANK(E45),0,1),2),3),4),5),6) -> 0 | AG45: =IF(ISBLANK(AE45),IF(ISBLANK(AC45),IF(ISBLANK(AA45),IF(ISBLANK(Y45),IF(ISBLANK(W45),IF(ISBLANK(U45),0,1),2),3),4),5),6) -> 0
C46: 0 | E46: 1 | G46: 2 | I46: 3 | K46: 4 | M46: 5 | O46: 6 | S46: 0 | U46: 1 | W46: 2 | Y46: 3 | AA46: 4 | AC46: 5 | AE46: 6
B49: A-17 | R49: F-17
Q50: =IF(ISBLANK(O50),IF(ISBLANK(M50),IF(ISBLANK(K50),IF(ISBLANK(I50),IF(ISBLANK(G50),IF(ISBLANK(E50),0,1),2),3),4),5),6) -> 0 | AG50: =IF(ISBLANK(AE50),IF(ISBLANK(AC50),IF(ISBLANK(AA50),IF(ISBLANK(Y50),IF(ISBLANK(W50),IF(ISBLANK(U50),0,1),2),3),4),5),6) -> 0
C51: 0 | E51: 1 | G51: 2 | I51: 3 | K51: 4 | M51: 5 | O51: 6 | S51: 0 | U51: 1 | W51: 2 | Y51: 3 | AA51: 4 | AC51: 5 | AE51: 6
B53: A-18 | R53: F-18
Q54: =IF(ISBLANK(O54),IF(ISBLANK(M54),IF(ISBLANK(K54),IF(ISBLANK(I54),IF(ISBLANK(G54),IF(ISBLANK(E54),0,1),2),3),4),5),6) -> 0 | AG54: =IF(ISBLANK(AE54),IF(ISBLANK(AC54),IF(ISBLANK(AA54),IF(ISBLANK(Y54),IF(ISBLANK(W54),IF(ISBLANK(U54),0,1),2),3),4),5),6) -> 0
C55: 0 | E55: 1 | G55: 2 | I55: 3 | K55: 4 | M55: 5 | O55: 6 | S55: 0 | U55: 1 | W55: 2 | Y55: 3 | AA55: 4 | AC55: 5 | AE55: 6
B57: A-19 | R57: F-19
Q58: =IF(ISBLANK(O58),IF(ISBLANK(M58),IF(ISBLANK(K58),IF(ISBLANK(I58),IF(ISBLANK(G58),IF(ISBLANK(E58),0,1),2),3),4),5),6) -> 0 | AG58: =IF(ISBLANK(AE58),IF(ISBLANK(AC58),IF(ISBLANK(AA58),IF(ISBLANK(Y58),IF(ISBLANK(W58),IF(ISBLANK(U58),0,1),2),3),4),5),6) -> 0
C59: 0 | E59: 1 | G59: 2 | I59: 3 | K59: 4 | M59: 5 | O59: 6 | S59: 0 | U59: 1 | W59: 2 | Y59: 3 | AA59: 4 | AC59: 5 | AE59: 6
B61: A-20
Q62: =IF(ISBLANK(O62),IF(ISBLANK(M62),IF(ISBLANK(K62),IF(ISBLANK(I62),IF(ISBLANK(G62),IF(ISBLANK(E62),0,1),2),3),4),5),6) -> 0 | AG62: =IF(ISBLANK(AE62),IF(ISBLANK(AC62),IF(ISBLANK(AA62),IF(ISBLANK(Y62),IF(ISBLANK(W62),IF(ISBLANK(U62),0,1),2),3),4),5),6) -> 0
C63: 0 | E63: 1 | G63: 2 | I63: 3 | K63: 4 | M63: 5 | O63: 6
B66: SEC-A4
...

Sheet summary
A1: object | B1: Y01 | C1: Y02 | D1: Y03 | E1: Y04 | F1: Y05 | G1: Y06 | H1: Y07 | I1: Y08 | J1: Y09 | K1: Y10 | L1: Y11 | M1: Y12 | N1: Y13 | O1: Y14 | P1: Y15 | Q1: Y16 | R1: Y17 | S1: Y18 | T1: Y19 | U1: Y20 | V1: Y21 | W1: Y22 | X1: Y23 | Y1: Y24 | Z1: Y25 | AA1: Y26 | AB1: Y27 | AC1: Y28 | AD1: Y29 | AE1: Y30 | AF1: Y48 | AG1: Y32 | AH1: Y49 | AI1: Y47 | AJ1: Y46 | AK1: Y33 | AL1: Y31 | AM1: Y36 | AN1: Y37 | AO1: Y34 | AP1: Y39 | AQ1: Y35 | AR1: Y38 | AS1: Y40 | AT1: Y41 | AU1: Y42 | AV1: Y43 | AW1: Y44 | AX1: Y45 | AY1: Y50 | AZ1: notes
A2: 1 | B2: =object_1!$Q$7 -> 0 | C2: =object_1!$Q$10 -> 0 | D2: =object_1!$Q$12 -> 0 | E2: =object_1!$Q$14 -> 0 | F2: =object_1!$Q$16 -> 0 | G2: =object_1!$Q$20 -> 0 | H2: =object_1!$Q$23 -> 0 | I2: =object_1!$Q$25 -> 0 | J2: =object_1!$Q$27 -> 0 | K2: =object_1!$Q$29 -> 0 | L2: =object_1!$Q$33 -> 0 | M2: =object_1!$Q$36 -> 0 | N2: =object_1!$Q$38 -> 0 | O2: =object_1!$Q$40 -> 0 | P2: =object_1!$Q$42 -> 0 | Q2: =object_1!$AG$7 -> 0 | R2: =object_1!$AG$10 -> 0 | S2: =object_1!$AG$12 -> 0 | T2: =object_1!$AG$14 -> 0 | U2: =object_1!$AG$16 -> 0 | V2: =object_1!$AG$20 -> 0 | W2: =object_1!$AG$23 -> 0 | X2: =object_1!$AG$25 -> 0 | Y2: =object_1!$AG$27 -> 0 | Z2: =object_1!$AG$29 -> 0 | AA2: =object_1!$AG$33 -> 0 | AB2: =object_1!$AG$36 -> 0 | AC2: =object_1!$AG$38 -> 0 | AD2: =object_1!$AG$40 -> 0 | AE2: =object_1!$AG$42 -> 0 | AF2: =object_1!$Q$50 -> 0 | AG2: =object_1!$Q$54 -> 0 | AH2: =object_1!$Q$58 -> 0 | AI2: =object_1!$Q$62 -> 0 | AJ2: =object_1!$AG$50 -> 0 | AK2: =object_1!$AG$54 -> 0 | AL2: =object_1!$AG$58 -> 0 | AM2: =object_1!$Q$68 -> 0 | AN2: =object_1!$Q$72 -> 0 | AO2: =object_1!$Q$76 -> 0 | AP2: =object_1!$AG$68 -> 0 | AQ2: =object_1!$AG$72 -> 0 | AR2: =object_1!$AG$76 -> 0 | AS2: =object_1!$Q$82 -> 0 | AT2: =object_1!$Q$86 -> 0 | AU2: =object_1!$Q$90 -> 0 | AV2: =object_1!$AG$82 -> 0 | AW2: =object_1!$AG$86 -> 0 | AX2: =object_1!$AG$76 -> 0 | AY2: =object_1!$Q$94 -> 0 | AZ2: =object_1!$S$93 -> 0
A3: 2 | B3: =object_2!$Q$7 -> 0 | C3: =object_2!$Q$10 -> 0 | D3: =object_2!$Q$12 -> 0 | E3: =object_2!$Q$14 -> 0 | F3: =object_2!$Q$16 -> 0 | G3: =object_2!$Q$20 -> 0 | H3: =object_2!$Q$23 -> 0 | I3: =object_2!$Q$25 -> 0 | J3: =object_2!$Q$27 -> 0 | K3: =object_2!$Q$29 -> 0 | L3: =object_2!$Q$33 -> 0 | M3: =object_2!$Q$36 -> 0 | N3: =object_2!$Q$38 -> 0 | O3: =object_2!$Q$40 -> 0 | P3: =object_2!$Q$42 -> 0 | Q3: =object_2!$AG$7 -> 0 | R3: =object_2!$AG$10 -> 0 | S3: =object_2!$AG$12 -> 0 | T3: =object_2!$AG$14 -> 0 | U3: =object_2!$AG$16 -> 0 | V3: =object_2!$AG$20 -> 0 | W3: =object_2!$AG$23 -> 0 | X3: =object_2!$AG$25 -> 0 | Y3: =object_2!$AG$27 -> 0 | Z3: =object_2!$AG$29 -> 0 | AA3: =object_2!$AG$33 -> 0 | AB3: =object_2!$AG$36 -> 0 | AC3: =object_2!$AG$38 -> 0 | AD3: =object_2!$AG$40 -> 0 | AE3: =object_2!$AG$42 -> 0 | AF3: =object_2!$Q$50 -> 0 | AG3: =object_2!$Q$54 -> 0 | AH3: =object_2!$Q$58 -> 0 | AI3: =object_2!$Q$62 -> 0 | AJ3: =object_2!$AG$50 -> 0 | AK3: =object_2!$AG$54 -> 0 | AL3: =object_2!$AG$58 -> 0 | AM3: =object_2!$Q$68 -> 0 | AN3: =object_2!$Q$72 -> 0 | AO3: =object_2!$Q$76 -> 0 | AP3: =object_2!$AG$68 -> 0 | AQ3: =object_2!$AG$72 -> 0 | AR3: =object_2!$AG$76 -> 0 | AS3: =object_2!$Q$82 -> 0 | AT3: =object_2!$Q$86 -> 0 | AU3: =object_2!$Q$90 -> 0 | AV3: =object_2!$AG$82 -> 0 | AW3: =object_2!$AG$86 -> 0 | AX3: =object_2!$AG$76 -> 0 | AY3: =object_2!$Q$94 -> 0 | AZ3: =object_2!$S$93 -> 0
A4: 3 | B4: =object_3!$Q$7 -> 0 | C4: =object_3!$Q$10 -> 0 | D4: =object_3!$Q$12 -> 0 | E4: =object_3!$Q$14 -> 0 | F4: =object_3!$Q$16 -> 0 | G4: =object_3!$Q$20 -> 0 | H4: =object_3!$Q$23 -> 0 | I4: =object_3!$Q$25 -> 0 | J4: =object_3!$Q$27 -> 0 | K4: =object_3!$Q$29 -> 0 | L4: =object_3!$Q$33 -> 0 | M4: =object_3!$Q$36 -> 0 | N4: =object_3!$Q$38 -> 0 | O4: =object_3!$Q$40 -> 0 | P4: =object_3!$Q$42 -> 0 | Q4: =object_3!$AG$7 -> 0 | R4: =object_3!$AG$10 -> 0 | S4: =object_3!$AG$12 -> 0 | T4: =object_3!$AG$14 -> 0 | U4: =object_3!$AG$16 -> 0 | V4: =object_3!$AG$20 -> 0 | W4: =object_3!$AG$23 -> 0 | X4: =object_3!$AG$25 -> 0 | Y4: =object_3!$AG$27 -> 0 | Z4: =object_3!$AG$29 -> 0 | AA4: =object_3!$AG$33 -> 0 | AB4: =object_3!$AG$36 -> 0 | AC4: =object_3!$AG$38 -> 0 | AD4: =object_3!$AG$40 -> 0 | AE4: =object_3!$AG$42 -> 0 | AF4: =object_3!$Q$50 -> 0 | AG4: =object_3!$Q$54 -> 0 | AH4: =object_3!$Q$58 -> 0 | AI4: =object_3!$Q$62 -> 0 | AJ4: =object_3!$AG$50 -> 0 | AK4: =object_3!$AG$54 -> 0 | AL4: =object_3!$AG$58 -> 0 | AM4: =object_3!$Q$68 -> 0 | AN4: =object_3!$Q$72 -> 0 | AO4: =object_3!$Q$76 -> 0 | AP4: =object_3!$AG$68 -> 0 | AQ4: =object_3!$AG$72 -> 0 | AR4: =object_3!$AG$76 -> 0 | AS4: =object_3!$Q$82 -> 0 | AT4: =object_3!$Q$86 -> 0 | AU4: =object_3!$Q$90 -> 0 | AV4: =object_3!$AG$82 -> 0 | AW4: =object_3!$AG$86 -> 0 | AX4: =object_3!$AG$76 -> 0 | AY4: =object_3!$Q$94 -> 0 | AZ4: =object_3!$S$93 -> 0
A5: 4 | B5: =object_4!$Q$7 -> 0 | C5: =object_4!$Q$10 -> 0 | D5: =object_4!$Q$12 -> 0 | E5: =object_4!$Q$14 -> 0 | F5: =object_4!$Q$16 -> 0 | G5: =object_4!$Q$20 -> 0 | H5: =object_4!$Q$23 -> 0 | I5: =object_4!$Q$25 -> 0 | J5: =object_4!$Q$27 -> 0 | K5: =object_4!$Q$29 -> 0 | L5: =object_4!$Q$33 -> 0 | M5: =object_4!$Q$36 -> 0 | N5: =object_4!$Q$38 -> 0 | O5: =object_4!$Q$40 -> 0 | P5: =object_4!$Q$42 -> 0 | Q5: =object_4!$AG$7 -> 0 | R5: =object_4!$AG$10 -> 0 | S5: =object_4!$AG$12 -> 0 | T5: =object_4!$AG$14 -> 0 | U5: =object_4!$AG$16 -> 0 | V5: =object_4!$AG$20 -> 0 | W5: =object_4!$AG$23 -> 0 | X5: =object_4!$AG$25 -> 0 | Y5: =object_4!$AG$27 -> 0 | Z5: =object_4!$AG$29 -> 0 | AA5: =object_4!$AG$33 -> 0 | AB5: =object_4!$AG$36 -> 0 | AC5: =object_4!$AG$38 -> 0 | AD5: =object_4!$AG$40 -> 0 | AE5: =object_4!$AG$42 -> 0 | AF5: =object_4!$Q$50 -> 0 | AG5: =object_4!$Q$54 -> 0 | AH5: =object_4!$Q$58 -> 0 | AI5: =object_4!$Q$62 -> 0 | AJ5: =object_4!$AG$50 -> 0 | AK5: =object_4!$AG$54 -> 0 | AL5: =object_4!$AG$58 -> 0 | AM5: =object_4!$Q$68 -> 0 | AN5: =object_4!$Q$72 -> 0 | AO5: =object_4!$Q$76 -> 0 | AP5: =object_4!$AG$68 -> 0 | AQ5: =object_4!$AG$72 -> 0 | AR5: =object_4!$AG$76 -> 0 | AS5: =object_4!$Q$82 -> 0 | AT5: =object_4!$Q$86 -> 0 | AU5: =object_4!$Q$90 -> 0 | AV5: =object_4!$AG$82 -> 0 | AW5: =object_4!$AG$86 -> 0 | AX5: =object_4!$AG$76 -> 0 | AY5: =object_4!$Q$94 -> 0 | AZ5: =object_4!$S$93 -> 0
