Workbook

Sheet beer_1
B1: Date
B3: Name: | R3: Beer#: | S3: 1
B5: Aroma | R5: Flavour
B6: Malt | R6: Malt
Q7: 1 | AG7: 1
C8: 0 | E8: 1 | G8: 2 | I8: 3 | K8: 4 | M8: 5 | O8: 6 | S8: 0 | U8: 1 | W8: 2 | Y8: 3 | AA8: 4 | AC8: 5 | AE8: 6
E10: Cereals, flour, grains | Q10: 2 | U10: Cereals, flour, grains | AG10: 3
E12: Bread crust | Q12: 2 | U12: Bread crust | AG12: 1
E14: Caramel | Q14: 1 | U14: Caramel | AG14: 0
E16: Smoked, burnt toast | Q16: 0 | U16: Smoked, burnt toast | AG16: 1
B19: Hops | R19: Hops
Q20: 2 | AG20: 2
C21: 0 | E21: 1 | G21: 2 | I21: 3 | K21: 4 | M21: 5 | O21: 6 | S21: 0 | U21: 1 | W21: 2 | Y21: 3 | AA21: 4 | AC21: 5 | AE21: 6
E23: Citrus | Q23: 1 | U23: Citrus | AG23: 1
E25: Tropical fruit | Q25: 1 | U25: Tropical fruit | AG25: 1
E27: Noble hops (dried herbs, dried grass, hay) | Q27: 1 | U27: Noble hops (dried herbs, dried grass, hay) | AG27: 2
E29: Pine, woody, resinous | Q29: 1 | U29: Pine, woody, resinous | AG29: 1
B32: Esters | R32: Esters
Q33: 3 | AG33: 2
C34: 0 | E34: 1 | G34: 2 | I34: 3 | K34: 4 | M34: 5 | O34: 6 | S34: 0 | U34: 1 | W34: 2 | Y34: 3 | AA34: 4 | AC34: 5 | AE34: 6
E36: Ethyl acetate, solvent, nail polish | Q36: 2 | U36: Ethyl acetate, solvent, nail polish | AG36: 2
E38: Banana, pear, candy | Q38: 1 | U38: Banana, pear, candy | AG38: 1
E40: Flowers, roses | Q40: 1 | U40: Flowers, roses | AG40: 1
E42: Sweet, fruity, apples | Q42: 0 | U42: Sweet, fruity, apples | AG42: 1
B44: Acetaldehyde (green apples, peel) | R44: Acetaldehyde (green apples, peel)
Q45: =IF(ISBLANK(O45),IF(ISBLANK(M45),IF(ISBLANK(K45),IF(ISBLANK(I45),IF(ISBLANK(G45),IF(ISBLANK(E45),0,1),2),3),4),5),6) | AG45: =IF(ISBLANK(AE45),IF(ISBLANK(AC45),IF(ISBLANK(AA45),IF(ISBLANK(Y45),IF(ISBLANK(W45),IF(ISBLANK(U45),0,1),2),3),4),5),6)
C46: 0 | E46: 1 | G46: 2 | I46: 3 | K46: 4 | M46: 5 | O46: 6 | S46: 0 | U46: 1 | W46: 2 | Y46: 3 | AA46: 4 | AC46: 5 | AE46: 6
B49: Body | R49: Alcohol
Q50: 4 | AG50: 4
C51: 0 | E51: 1 | G51: 2 | I51: 3 | K51: 4 | M51: 5 | O51: 6 | S51: 0 | U51: 1 | W51: 2 | Y51: 3 | AA51: 4 | AC51: 5 | AE51: 6
B53: Bitterness | R53: Sweetness
Q54: 3 | AG54: 1
C55: 0 | E55: 1 | G55: 2 | I55: 3 | K55: 4 | M55: 5 | O55: 6 | S55: 0 | U55: 1 | W55: 2 | Y55: 3 | AA55: 4 | AC55: 5 | AE55: 6
B57: Carbonation | R57: Acidity/sourness
Q58: 3 | AG58: 1
C59: 0 | E59: 1 | G59: 2 | I59: 3 | K59: 4 | M59: 5 | O59: 6 | S59: 0 | U59: 1 | W59: 2 | Y59: 3 | AA59: 4 | AC59: 5 | AE59: 6
B61: Aftertaste
Q62: 4 | AG62: =IF(ISBLANK(AE62),IF(ISBLANK(AC62),IF(ISBLANK(AA62),IF(ISBLANK(Y62),IF(ISBLANK(W62),IF(ISBLANK(U62),0,1),2),3),4),5),6)
C63: 0 | E63: 1 | G63: 2 | I63: 3 | K63: 4 | M63: 5 | O63: 6
B66: Faults
...

Sheet beer_2
B1: Date
B3: Name: | R3: Beer#: | S3: 2
B5: Aroma | R5: Flavour
B6: Malt | R6: Malt
Q7: 1 | AG7: 1
C8: 0 | E8: 1 | G8: 2 | I8: 3 | K8: 4 | M8: 5 | O8: 6 | S8: 0 | U8: 1 | W8: 2 | Y8: 3 | AA8: 4 | AC8: 5 | AE8: 6
E10: Cereals, flour, grains | Q10: 3 | U10: Cereals, flour, grains | AG10: 3
E12: Bread crust | Q12: 1 | U12: Bread crust | AG12: 1
E14: Caramel | Q14: 0 | U14: Caramel | AG14: 0
E16: Smoked, burnt toast | Q16: 0 | U16: Smoked, burnt toast | AG16: 0
B19: Hops | R19: Hops
Q20: 0 | AG20: 0
C21: 0 | E21: 1 | G21: 2 | I21: 3 | K21: 4 | M21: 5 | O21: 6 | S21: 0 | U21: 1 | W21: 2 | Y21: 3 | AA21: 4 | AC21: 5 | AE21: 6
E23: Citrus | Q23: 1 | U23: Citrus | AG23: 1
E25: Tropical fruit | Q25: 0 | U25: Tropical fruit | AG25: 0
E27: Noble hops (dried herbs, dried grass, hay) | Q27: 0 | U27: Noble hops (dried herbs, dried grass, hay) | AG27: 1
E29: Pine, woody, resinous | Q29: 1 | U29: Pine, woody, resinous | AG29: 0
B32: Esters | R32: Esters
Q33: 2 | AG33: 0
C34: 0 | E34: 1 | G34: 2 | I34: 3 | K34: 4 | M34: 5 | O34: 6 | S34: 0 | U34: 1 | W34: 2 | Y34: 3 | AA34: 4 | AC34: 5 | AE34: 6
E36: Ethyl acetate, solvent, nail polish | Q36: 0 | U36: Ethyl acetate, solvent, nail polish | AG36: 0
E38: Banana, pear, candy | Q38: 0 | U38: Banana, pear, candy | AG38: 1
E40: Flowers, roses | Q40: 0 | U40: Flowers, roses | AG40: 0
E42: Sweet, fruity, apples | Q42: 0 | U42: Sweet, fruity, apples | AG42: 1
B44: Acetaldehyde (green apples, peel) | R44: Acetaldehyde (green apples, peel)
Q45: =IF(ISBLANK(O45),IF(ISBLANK(M45),IF(ISBLANK(K45),IF(ISBLANK(I45),IF(ISBLANK(G45),IF(ISBLANK(E45),0,1),2),3),4),5),6) | AG45: =IF(ISBLANK(AE45),IF(ISBLANK(AC45),IF(ISBLANK(AA45),IF(ISBLANK(Y45),IF(ISBLANK(W45),IF(ISBLANK(U45),0,1),2),3),4),5),6)
C46: 0 | E46: 1 | G46: 2 | I46: 3 | K46: 4 | M46: 5 | O46: 6 | S46: 0 | U46: 1 | W46: 2 | Y46: 3 | AA46: 4 | AC46: 5 | AE46: 6
B49: Body | R49: Alcohol
Q50: 2 | AG50: 1
C51: 0 | E51: 1 | G51: 2 | I51: 3 | K51: 4 | M51: 5 | O51: 6 | S51: 0 | U51: 1 | W51: 2 | Y51: 3 | AA51: 4 | AC51: 5 | AE51: 6
B53: Bitterness | R53: Sweetness
Q54: 1 | AG54: 2
C55: 0 | E55: 1 | G55: 2 | I55: 3 | K55: 4 | M55: 5 | O55: 6 | S55: 0 | U55: 1 | W55: 2 | Y55: 3 | AA55: 4 | AC55: 5 | AE55: 6
B57: Carbonation | R57: Acidity/sourness
Q58: 1 | AG58: 1
C59: 0 | E59: 1 | G59: 2 | I59: 3 | K59: 4 | M59: 5 | O59: 6 | S59: 0 | U59: 1 | W59: 2 | Y59: 3 | AA59: 4 | AC59: 5 | AE59: 6
B61: Aftertaste
Q62: 2 | AG62: =IF(ISBLANK(AE62),IF(ISBLANK(AC62),IF(ISBLANK(AA62),IF(ISBLANK(Y62),IF(ISBLANK(W62),IF(ISBLANK(U62),0,1),2),3),4),5),6)
C63: 0 | E63: 1 | G63: 2 | I63: 3 | K63: 4 | M63: 5 | O63: 6
B66: Faults
...

Sheet beer_3
B1: Date
B3: Name: | R3: Beer#: | S3: 3
B5: Aroma | R5: Flavour
B6: Malt | R6: Malt
Q7: 1 | AG7: 1
C8: 0 | E8: 1 | G8: 2 | I8: 3 | K8: 4 | M8: 5 | O8: 6 | S8: 0 | U8: 1 | W8: 2 | Y8: 3 | AA8: 4 | AC8: 5 | AE8: 6
E10: Cereals, flour, grains | Q10: 2 | U10: Cereals, flour, grains | AG10: 3
E12: Bread crust | Q12: 1 | U12: Bread crust | AG12: 1
E14: Caramel | Q14: 1 | U14: Caramel | AG14: 0
E16: Smoked, burnt toast | Q16: 0 | U16: Smoked, burnt toast | AG16: 0
B19: Hops | R19: Hops
Q20: 1 | AG20: 1
C21: 0 | E21: 1 | G21: 2 | I21: 3 | K21: 4 | M21: 5 | O21: 6 | S21: 0 | U21: 1 | W21: 2 | Y21: 3 | AA21: 4 | AC21: 5 | AE21: 6
E23: Citrus | Q23: 1 | U23: Citrus | AG23: 1
E25: Tropical fruit | Q25: 0 | U25: Tropical fruit | AG25: 0
E27: Noble hops (dried herbs, dried grass, hay) | Q27: 1 | U27: Noble hops (dried herbs, dried grass, hay) | AG27: 1
E29: Pine, woody, resinous | Q29: 1 | U29: Pine, woody, resinous | AG29: 0
B32: Esters | R32: Esters
Q33: 3 | AG33: 1
C34: 0 | E34: 1 | G34: 2 | I34: 3 | K34: 4 | M34: 5 | O34: 6 | S34: 0 | U34: 1 | W34: 2 | Y34: 3 | AA34: 4 | AC34: 5 | AE34: 6
E36: Ethyl acetate, solvent, nail polish | Q36: 1 | U36: Ethyl acetate, solvent, nail polish | AG36: 1
E38: Banana, pear, candy | Q38: 1 | U38: Banana, pear, candy | AG38: 1
E40: Flowers, roses | Q40: 1 | U40: Flowers, roses | AG40: 1
E42: Sweet, fruity, apples | Q42: 0 | U42: Sweet, fruity, apples | AG42: 1
B44: Acetaldehyde (green apples, peel) | R44: Acetaldehyde (green apples, peel)
Q45: =IF(ISBLANK(O45),IF(ISBLANK(M45),IF(ISBLANK(K45),IF(ISBLANK(I45),IF(ISBLANK(G45),IF(ISBLANK(E45),0,1),2),3),4),5),6) | AG45: =IF(ISBLANK(AE45),IF(ISBLANK(AC45),IF(ISBLANK(AA45),IF(ISBLANK(Y45),IF(ISBLANK(W45),IF(ISBLANK(U45),0,1),2),3),4),5),6)
C46: 0 | E46: 1 | G46: 2 | I46: 3 | K46: 4 | M46: 5 | O46: 6 | S46: 0 | U46: 1 | W46: 2 | Y46: 3 | AA46: 4 | AC46: 5 | AE46: 6
B49: Body | R49: Alcohol
Q50: 3 | AG50: 4
C51: 0 | E51: 1 | G51: 2 | I51: 3 | K51: 4 | M51: 5 | O51: 6 | S51: 0 | U51: 1 | W51: 2 | Y51: 3 | AA51: 4 | AC51: 5 | AE51: 6
B53: Bitterness | R53: Sweetness
Q54: 2 | AG54: 2
C55: 0 | E55: 1 | G55: 2 | I55: 3 | K55: 4 | M55: 5 | O55: 6 | S55: 0 | U55: 1 | W55: 2 | Y55: 3 | AA55: 4 | AC55: 5 | AE55: 6
B57: Carbonation | R57: Acidity/sourness
Q58: 2 | AG58: 1
C59: 0 | E59: 1 | G59: 2 | I59: 3 | K59: 4 | M59: 5 | O59: 6 | S59: 0 | U59: 1 | W59: 2 | Y59: 3 | AA59: 4 | AC59: 5 | AE59: 6
B61: Aftertaste
Q62: 3 | AG62: =IF(ISBLANK(AE62),IF(ISBLANK(AC62),IF(ISBLANK(AA62),IF(ISBLANK(Y62),IF(ISBLANK(W62),IF(ISBLANK(U62),0,1),2),3),4),5),6)
C63: 0 | E63: 1 | G63: 2 | I63: 3 | K63: 4 | M63: 5 | O63: 6
B66: Faults
...

Sheet beer_4
B1: Date
B3: Name: | R3: Beer#: | S3: 4
B5: Aroma | R5: Flavour
B6: Malt | R6: Malt
Q7: 2 | AG7: 2
C8: 0 | E8: 1 | G8: 2 | I8: 3 | K8: 4 | M8: 5 | O8: 6 | S8: 0 | U8: 1 | W8: 2 | Y8: 3 | AA8: 4 | AC8: 5 | AE8: 6
E10: Cereals, flour, grains | Q10: 3 | U10: Cereals, flour, grains | AG10: 4
E12: Bread crust | Q12: 2 | U12: Bread crust | AG12: 2
E14: Caramel | Q14: 2 | U14: Caramel | AG14: 1
E16: Smoked, burnt toast | Q16: 1 | U16: Smoked, burnt toast | AG16: 1
B19: Hops | R19: Hops
Q20: 2 | AG20: 2
C21: 0 | E21: 1 | G21: 2 | I21: 3 | K21: 4 | M21: 5 | O21: 6 | S21: 0 | U21: 1 | W21: 2 | Y21: 3 | AA21: 4 | AC21: 5 | AE21: 6
E23: Citrus | Q23: 1 | U23: Citrus | AG23: 1
E25: Tropical fruit | Q25: 1 | U25: Tropical fruit | AG25: 1
E27: Noble hops (dried herbs, dried grass, hay) | Q27: 1 | U27: Noble hops (dried herbs, dried grass, hay) | AG27: 2
E29: Pine, woody, resinous | Q29: 1 | U29: Pine, woody, resinous | AG29: 1
B32: Esters | R32: Esters
Q33: 4 | AG33: 2
C34: 0 | E34: 1 | G34: 2 | I34: 3 | K34: 4 | M34: 5 | O34: 6 | S34: 0 | U34: 1 | W34: 2 | Y34: 3 | AA34: 4 | AC34: 5 | AE34: 6
E36: Ethyl acetate, solvent, nail polish | Q36: 2 | U36: Ethyl acetate, solvent, nail polish | AG36: 2
E38: Banana, pear, candy | Q38: 2 | U38: Banana, pear, candy | AG38: 2
E40: Flowers, roses | Q40: 1 | U40: Flowers, roses | AG40: 1
E42: Sweet, fruity, apples | Q42: 1 | U42: Sweet, fruity, apples | AG42: 2
B44: Acetaldehyde (green apples, peel) | R44: Acetaldehyde (green apples, peel)
Q45: =IF(ISBLANK(O45),IF(ISBLANK(M45),IF(ISBLANK(K45),IF(ISBLANK(I45),IF(ISBLANK(G45),IF(ISBLANK(E45),0,1),2),3),4),5),6) | AG45: =IF(ISBLANK(AE45),IF(ISBLANK(AC45),IF(ISBLANK(AA45),IF(ISBLANK(Y45),IF(ISBLANK(W45),IF(ISBLANK(U45),0,1),2),3),4),5),6)
C46: 0 | E46: 1 | G46: 2 | I46: 3 | K46: 4 | M46: 5 | O46: 6 | S46: 0 | U46: 1 | W46: 2 | Y46: 3 | AA46: 4 | AC46: 5 | AE46: 6
B49: Body | R49: Alcohol
Q50: 4 | AG50: 5
C51: 0 | E51: 1 | G51: 2 | I51: 3 | K51: 4 | M51: 5 | O51: 6 | S51: 0 | U51: 1 | W51: 2 | Y51: 3 | AA51: 4 | AC51: 5 | AE51: 6
B53: Bitterness | R53: Sweetness
Q54: 3 | AG54: 2
C55: 0 | E55: 1 | G55: 2 | I55: 3 | K55: 4 | M55: 5 | O55: 6 | S55: 0 | U55: 1 | W55: 2 | Y55: 3 | AA55: 4 | AC55: 5 | AE55: 6
B57: Carbonation | R57: Acidity/sourness
Q58: 3 | AG58: 1
C59: 0 | E59: 1 | G59: 2 | I59: 3 | K59: 4 | M59: 5 | O59: 6 | S59: 0 | U59: 1 | W59: 2 | Y59: 3 | AA59: 4 | AC59: 5 | AE59: 6
B61: Aftertaste
Q62: 4 | AG62: =IF(ISBLANK(AE62),IF(ISBLANK(AC62),IF(ISBLANK(AA62),IF(ISBLANK(Y62),IF(ISBLANK(W62),IF(ISBLANK(U62),0,1),2),3),4),5),6)
C63: 0 | E63: 1 | G63: 2 | I63: 3 | K63: 4 | M63: 5 | O63: 6
B66: Faults
...

Sheet beer_5
B1: Date
B3: Name: | R3: Beer#: | S3: 5
B5: Aroma | R5: Flavour
B6: Malt | R6: Malt
Q7: 1 | AG7: 1
C8: 0 | E8: 1 | G8: 2 | I8: 3 | K8: 4 | M8: 5 | O8: 6 | S8: 0 | U8: 1 | W8: 2 | Y8: 3 | AA8: 4 | AC8: 5 | AE8: 6
E10: Cereals, flour, grains | Q10: 2 | U10: Cereals, flour, grains | AG10: 3
E12: Bread crust | Q12: 2 | U12: Bread crust | AG12: 1
E14: Caramel | Q14: 1 | U14: Caramel | AG14: 0
E16: Smoked, burnt toast | Q16: 0 | U16: Smoked, burnt toast | AG16: 1
B19: Hops | R19: Hops
Q20: 2 | AG20: 2
C21: 0 | E21: 1 | G21: 2 | I21: 3 | K21: 4 | M21: 5 | O21: 6 | S21: 0 | U21: 1 | W21: 2 | Y21: 3 | AA21: 4 | AC21: 5 | AE21: 6
E23: Citrus | Q23: 2 | U23: Citrus | AG23: 2
E25: Tropical fruit | Q25: 1 | U25: Tropical fruit | AG25: 1
E27: Noble hops (dried herbs, dried grass, hay) | Q27: 2 | U27: Noble hops (dried herbs, dried grass, hay) | AG27: 2
E29: Pine, woody, resinous | Q29: 2 | U29: Pine, woody, resinous | AG29: 1
B32: Esters | R32: Esters
Q33: 3 | AG33: 1
C34: 0 | E34: 1 | G34: 2 | I34: 3 | K34: 4 | M34: 5 | O34: 6 | S34: 0 | U34: 1 | W34: 2 | Y34: 3 | AA34: 4 | AC34: 5 | AE34: 6
E36: Ethyl acetate, solvent, nail polish | Q36: 1 | U36: Ethyl acetate, solvent, nail polish | AG36: 1
E38: Banana, pear, candy | Q38: 1 | U38: Banana, pear, candy | AG38: 1
E40: Flowers, roses | Q40: 1 | U40: Flowers, roses | AG40: 1
E42: Sweet, fruity, apples | Q42: 0 | U42: Sweet, fruity, apples | AG42: 1
B44: Acetaldehyde (green apples, peel) | R44: Acetaldehyde (green apples, peel)
Q45: =IF(ISBLANK(O45),IF(ISBLANK(M45),IF(ISBLANK(K45),IF(ISBLANK(I45),IF(ISBLANK(G45),IF(ISBLANK(E45),0,1),2),3),4),5),6) | AG45: =IF(ISBLANK(AE45),IF(ISBLANK(AC45),IF(ISBLANK(AA45),IF(ISBLANK(Y45),IF(ISBLANK(W45),IF(ISBLANK(U45),0,1),2),3),4),5),6)
C46: 0 | E46: 1 | G46: 2 | I46: 3 | K46: 4 | M46: 5 | O46: 6 | S46: 0 | U46: 1 | W46: 2 | Y46: 3 | AA46: 4 | AC46: 5 | AE46: 6
B49: Body | R49: Alcohol
Q50: 3 | AG50: 4
C51: 0 | E51: 1 | G51: 2 | I51: 3 | K51: 4 | M51: 5 | O51: 6 | S51: 0 | U51: 1 | W51: 2 | Y51: 3 | AA51: 4 | AC51: 5 | AE51: 6
B53: Bitterness | R53: Sweetness
Q54: 4 | AG54: 1
C55: 0 | E55: 1 | G55: 2 | I55: 3 | K55: 4 | M55: 5 | O55: 6 | S55: 0 | U55: 1 | W55: 2 | Y55: 3 | AA55: 4 | AC55: 5 | AE55: 6
B57: Carbonation | R57: Acidity/sourness
Q58: 3 | AG58: 1
C59: 0 | E59: 1 | G59: 2 | I59: 3 | K59: 4 | M59: 5 | O59: 6 | S59: 0 | U59: 1 | W59: 2 | Y59: 3 | AA59: 4 | AC59: 5 | AE59: 6
B61: Aftertaste
Q62: 4 | AG62: =IF(ISBLANK(AE62),IF(ISBLANK(AC62),IF(ISBLANK(AA62),IF(ISBLANK(Y62),IF(ISBLANK(W62),IF(ISBLANK(U62),0,1),2),3),4),5),6)
C63: 0 | E63: 1 | G63: 2 | I63: 3 | K63: 4 | M63: 5 | O63: 6
B66: Faults
...

Sheet beer_6
B1: Date
B3: Name: | R3: Beer#: | S3: 6
B5: Aroma | R5: Flavour
B6: Malt | R6: Malt
Q7: 1 | AG7: 1
C8: 0 | E8: 1 | G8: 2 | I8: 3 | K8: 4 | M8: 5 | O8: 6 | S8: 0 | U8: 1 | W8: 2 | Y8: 3 | AA8: 4 | AC8: 5 | AE8: 6
E10: Cereals, flour, grains | Q10: 2 | U10: Cereals, flour, grains | AG10: 3
E12: Bread crust | Q12: 2 | U12: Bread crust | AG12: 1
E14: Caramel | Q14: 1 | U14: Caramel | AG14: 1
E16: Smoked, burnt toast | Q16: 0 | U16: Smoked, burnt toast | AG16: 1
B19: Hops | R19: Hops
Q20: 2 | AG20: 1
C21: 0 | E21: 1 | G21: 2 | I21: 3 | K21: 4 | M21: 5 | O21: 6 | S21: 0 | U21: 1 | W21: 2 | Y21: 3 | AA21: 4 | AC21: 5 | AE21: 6
E23: Citrus | Q23: 1 | U23: Citrus | AG23: 1
E25: Tropical fruit | Q25: 1 | U25: Tropical fruit | AG25: 0
E27: Noble hops (dried herbs, dried grass, hay) | Q27: 1 | U27: Noble hops (dried herbs, dried grass, hay) | AG27: 2
E29: Pine, woody, resinous | Q29: 1 | U29: Pine, woody, resinous | AG29: 1
B32: Esters | R32: Esters
Q33: 3 | AG33: 1
C34: 0 | E34: 1 | G34: 2 | I34: 3 | K34: 4 | M34: 5 | O34: 6 | S34: 0 | U34: 1 | W34: 2 | Y34: 3 | AA34: 4 | AC34: 5 | AE34: 6
E36: Ethyl acetate, solvent, nail polish | Q36: 1 | U36: Ethyl acetate, solvent, nail polish | AG36: 1
E38: Banana, pear, candy | Q38: 1 | U38: Banana, pear, candy | AG38: 1
E40: Flowers, roses | Q40: 1 | U40: Flowers, roses | AG40: 1
E42: Sweet, fruity, apples | Q42: 0 | U42: Sweet, fruity, apples | AG42: 1
B44: Acetaldehyde (green apples, peel) | R44: Acetaldehyde (green apples, peel)
Q45: =IF(ISBLANK(O45),IF(ISBLANK(M45),IF(ISBLANK(K45),IF(ISBLANK(I45),IF(ISBLANK(G45),IF(ISBLANK(E45),0,1),2),3),4),5),6) | AG45: =IF(ISBLANK(AE45),IF(ISBLANK(AC45),IF(ISBLANK(AA45),IF(ISBLANK(Y45),IF(ISBLANK(W45),IF(ISBLANK(U45),0,1),2),3),4),5),6)
C46: 0 | E46: 1 | G46: 2 | I46: 3 | K46: 4 | M46: 5 | O46: 6 | S46: 0 | U46: 1 | W46: 2 | Y46: 3 | AA46: 4 | AC46: 5 | AE46: 6
B49: Body | R49: Alcohol
Q50: 3 | AG50: 4
C51: 0 | E51: 1 | G51: 2 | I51: 3 | K51: 4 | M51: 5 | O51: 6 | S51: 0 | U51: 1 | W51: 2 | Y51: 3 | AA51: 4 | AC51: 5 | AE51: 6
B53: Bitterness | R53: Sweetness
Q54: 3 | AG54: 2
C55: 0 | E55: 1 | G55: 2 | I55: 3 | K55: 4 | M55: 5 | O55: 6 | S55: 0 | U55: 1 | W55: 2 | Y55: 3 | AA55: 4 | AC55: 5 | AE55: 6
B57: Carbonation | R57: Acidity/sourness
Q58: 3 | AG58: 1
C59: 0 | E59: 1 | G59: 2 | I59: 3 | K59: 4 | M59: 5 | O59: 6 | S59: 0 | U59: 1 | W59: 2 | Y59: 3 | AA59: 4 | AC59: 5 | AE59: 6
B61: Aftertaste
Q62: 4 | AG62: =IF(ISBLANK(AE62),IF(ISBLANK(AC62),IF(ISBLANK(AA62),IF(ISBLANK(Y62),IF(ISBLANK(W62),IF(ISBLANK(U62),0,1),2),3),4),5),6)
C63: 0 | E63: 1 | G63: 2 | I63: 3 | K63: 4 | M63: 5 | O63: 6
B66: Faults
...

Sheet beer_7
B1: Date
B3: Name: | R3: Beer#: | S3: 7
B5: Aroma | R5: Flavour
B6: Malt | R6: Malt
Q7: 0 | AG7: 1
C8: 0 | E8: 1 | G8: 2 | I8: 3 | K8: 4 | M8: 5 | O8: 6 | S8: 0 | U8: 1 | W8: 2 | Y8: 3 | AA8: 4 | AC8: 5 | AE8: 6
E10: Cereals, flour, grains | Q10: 2 | U10: Cereals, flour, grains | AG10: 3
E12: Bread crust | Q12: 1 | U12: Bread crust | AG12: 1
E14: Caramel | Q14: 1 | U14: Caramel | AG14: 0
E16: Smoked, burnt toast | Q16: 0 | U16: Smoked, burnt toast | AG16: 0
B19: Hops | R19: Hops
Q20: 2 | AG20: 2
C21: 0 | E21: 1 | G21: 2 | I21: 3 | K21: 4 | M21: 5 | O21: 6 | S21: 0 | U21: 1 | W21: 2 | Y21: 3 | AA21: 4 | AC21: 5 | AE21: 6
E23: Citrus | Q23: 2 | U23: Citrus | AG23: 1
E25: Tropical fruit | Q25: 1 | U25: Tropical fruit | AG25: 1
E27: Noble hops (dried herbs, dried grass, hay) | Q27: 1 | U27: Noble hops (dried herbs, dried grass, hay) | AG27: 2
E29: Pine, woody, resinous | Q29: 1 | U29: Pine, woody, resinous | AG29: 1
B32: Esters | R32: Esters
Q33: 3 | AG33: 1
C34: 0 | E34: 1 | G34: 2 | I34: 3 | K34: 4 | M34: 5 | O34: 6 | S34: 0 | U34: 1 | W34: 2 | Y34: 3 | AA34: 4 | AC34: 5 | AE34: 6
E36: Ethyl acetate, solvent, nail polish | Q36: 1 | U36: Ethyl acetate, solvent, nail polish | AG36: 1
E38: Banana, pear, candy | Q38: 1 | U38: Banana, pear, candy | AG38: 1
E40: Flowers, roses | Q40: 1 | U40: Flowers, roses | AG40: 1
E42: Sweet, fruity, apples | Q42: 0 | U42: Sweet, fruity, apples | AG42: 2
B44: Acetaldehyde (green apples, peel) | R44: Acetaldehyde (green apples, peel)
Q45: =IF(ISBLANK(O45),IF(ISBLANK(M45),IF(ISBLANK(K45),IF(ISBLANK(I45),IF(ISBLANK(G45),IF(ISBLANK(E45),0,1),2),3),4),5),6) | AG45: =IF(ISBLANK(AE45),IF(ISBLANK(AC45),IF(ISBLANK(AA45),IF(ISBLANK(Y45),IF(ISBLANK(W45),IF(ISBLANK(U45),0,1),2),3),4),5),6)
C46: 0 | E46: 1 | G46: 2 | I46: 3 | K46: 4 | M46: 5 | O46: 6 | S46: 0 | U46: 1 | W46: 2 | Y46: 3 | AA46: 4 | AC46: 5 | AE46: 6
B49: Body | R49: Alcohol
Q50: 3 | AG50: 4
C51: 0 | E51: 1 | G51: 2 | I51: 3 | K51: 4 | M51: 5 | O51: 6 | S51: 0 | U51: 1 | W51: 2 | Y51: 3 | AA51: 4 | AC51: 5 | AE51: 6
B53: Bitterness | R53: Sweetness
Q54: 3 | AG54: 2
C55: 0 | E55: 1 | G55: 2 | I55: 3 | K55: 4 | M55: 5 | O55: 6 | S55: 0 | U55: 1 | W55: 2 | Y55: 3 | AA55: 4 | AC55: 5 | AE55: 6
B57: Carbonation | R57: Acidity/sourness
Q58: 3 | AG58: 1
C59: 0 | E59: 1 | G59: 2 | I59: 3 | K59: 4 | M59: 5 | O59: 6 | S59: 0 | U59: 1 | W59: 2 | Y59: 3 | AA59: 4 | AC59: 5 | AE59: 6
B61: Aftertaste
Q62: 4 | AG62: =IF(ISBLANK(AE62),IF(ISBLANK(AC62),IF(ISBLANK(AA62),IF(ISBLANK(Y62),IF(ISBLANK(W62),IF(ISBLANK(U62),0,1),2),3),4),5),6)
C63: 0 | E63: 1 | G63: 2 | I63: 3 | K63: 4 | M63: 5 | O63: 6
B66: Faults
...

Sheet beer_8
B1: Date
B3: Name: | R3: Beer#: | S3: 8
B5: Aroma | R5: Flavour
B6: Malt | R6: Malt
Q7: 1 | AG7: 2
C8: 0 | E8: 1 | G8: 2 | I8: 3 | K8: 4 | M8: 5 | O8: 6 | S8: 0 | U8: 1 | W8: 2 | Y8: 3 | AA8: 4 | AC8: 5 | AE8: 6
E10: Cereals, flour, grains | Q10: 2 | U10: Cereals, flour, grains | AG10: 3
E12: Bread crust | Q12: 2 | U12: Bread crust | AG12: 2
E14: Caramel | Q14: 1 | U14: Caramel | AG14: 1
E16: Smoked, burnt toast | Q16: 0 | U16: Smoked, burnt toast | AG16: 1
B19: Hops | R19: Hops
Q20: 2 | AG20: 2
C21: 0 | E21: 1 | G21: 2 | I21: 3 | K21: 4 | M21: 5 | O21: 6 | S21: 0 | U21: 1 | W21: 2 | Y21: 3 | AA21: 4 | AC21: 5 | AE21: 6
E23: Citrus | Q23: 1 | U23: Citrus | AG23: 1
E25: Tropical fruit | Q25: 1 | U25: Tropical fruit | AG25: 0
E27: Noble hops (dried herbs, dried grass, hay) | Q27: 1 | U27: Noble hops (dried herbs, dried grass, hay) | AG27: 2
E29: Pine, woody, resinous | Q29: 1 | U29: Pine, woody, resinous | AG29: 1
B32: Esters | R32: Esters
Q33: 4 | AG33: 2
C34: 0 | E34: 1 | G34: 2 | I34: 3 | K34: 4 | M34: 5 | O34: 6 | S34: 0 | U34: 1 | W34: 2 | Y34: 3 | AA34: 4 | AC34: 5 | AE34: 6
E36: Ethyl acetate, solvent, nail polish | Q36: 2 | U36: Ethyl acetate, solvent, nail polish | AG36: 2
E38: Banana, pear, candy | Q38: 1 | U38: Banana, pear, candy | AG38: 1
E40: Flowers, roses | Q40: 1 | U40: Flowers, roses | AG40: 1
E42: Sweet, fruity, apples | Q42: 0 | U42: Sweet, fruity, apples | AG42: 1
B44: Acetaldehyde (green apples, peel) | R44: Acetaldehyde (green apples, peel)
Q45: =IF(ISBLANK(O45),IF(ISBLANK(M45),IF(ISBLANK(K45),IF(ISBLANK(I45),IF(ISBLANK(G45),IF(ISBLANK(E45),0,1),2),3),4),5),6) | AG45: =IF(ISBLANK(AE45),IF(ISBLANK(AC45),IF(ISBLANK(AA45),IF(ISBLANK(Y45),IF(ISBLANK(W45),IF(ISBLANK(U45),0,1),2),3),4),5),6)
C46: 0 | E46: 1 | G46: 2 | I46: 3 | K46: 4 | M46: 5 | O46: 6 | S46: 0 | U46: 1 | W46: 2 | Y46: 3 | AA46: 4 | AC46: 5 | AE46: 6
B49: Body | R49: Alcohol
Q50: 4 | AG50: 5
C51: 0 | E51: 1 | G51: 2 | I51: 3 | K51: 4 | M51: 5 | O51: 6 | S51: 0 | U51: 1 | W51: 2 | Y51: 3 | AA51: 4 | AC51: 5 | AE51: 6
B53: Bitterness | R53: Sweetness
Q54: 3 | AG54: 1
C55: 0 | E55: 1 | G55: 2 | I55: 3 | K55: 4 | M55: 5 | O55: 6 | S55: 0 | U55: 1 | W55: 2 | Y55: 3 | AA55: 4 | AC55: 5 | AE55: 6
B57: Carbonation | R57: Acidity/sourness
Q58: 3 | AG58: 1
C59: 0 | E59: 1 | G59: 2 | I59: 3 | K59: 4 | M59: 5 | O59: 6 | S59: 0 | U59: 1 | W59: 2 | Y59: 3 | AA59: 4 | AC59: 5 | AE59: 6
B61: Aftertaste
Q62: 4 | AG62: =IF(ISBLANK(AE62),IF(ISBLANK(AC62),IF(ISBLANK(AA62),IF(ISBLANK(Y62),IF(ISBLANK(W62),IF(ISBLANK(U62),0,1),2),3),4),5),6)
C63: 0 | E63: 1 | G63: 2 | I63: 3 | K63: 4 | M63: 5 | O63: 6
B66: Faults
...

Sheet beer_9
B1: Date
B3: Name: | R3: Beer#: | S3: 9
B5: Aroma | R5: Flavour
B6: Malt | R6: Malt
Q7: 1 | AG7: 1
C8: 0 | E8: 1 | G8: 2 | I8: 3 | K8: 4 | M8: 5 | O8: 6 | S8: 0 | U8: 1 | W8: 2 | Y8: 3 | AA8: 4 | AC8: 5 | AE8: 6
E10: Cereals, flour, grains | Q10: 2 | U10: Cereals, flour, grains | AG10: 3
E12: Bread crust | Q12: 2 | U12: Bread crust | AG12: 1
E14: Caramel | Q14: 1 | U14: Caramel | AG14: 0
E16: Smoked, burnt toast | Q16: 0 | U16: Smoked, burnt toast | AG16: 1
B19: Hops | R19: Hops
Q20: 2 | AG20: 2
C21: 0 | E21: 1 | G21: 2 | I21: 3 | K21: 4 | M21: 5 | O21: 6 | S21: 0 | U21: 1 | W21: 2 | Y21: 3 | AA21: 4 | AC21: 5 | AE21: 6
E23: Citrus | Q23: 2 | U23: Citrus | AG23: 1
E25: Tropical fruit | Q25: 1 | U25: Tropical fruit | AG25: 1
E27: Noble hops (dried herbs, dried grass, hay) | Q27: 1 | U27: Noble hops (dried herbs, dried grass, hay) | AG27: 2
E29: Pine, woody, resinous | Q29: 2 | U29: Pine, woody, resinous | AG29: 1
B32: Esters | R32: Esters
Q33: 3 | AG33: 1
C34: 0 | E34: 1 | G34: 2 | I34: 3 | K34: 4 | M34: 5 | O34: 6 | S34: 0 | U34: 1 | W34: 2 | Y34: 3 | AA34: 4 | AC34: 5 | AE34: 6
E36: Ethyl acetate, solvent, nail polish | Q36: 2 | U36: Ethyl acetate, solvent, nail polish | AG36: 1
E38: Banana, pear, candy | Q38: 1 | U38: Banana, pear, candy | AG38: 1
E40: Flowers, roses | Q40: 1 | U40: Flowers, roses | AG40: 1
E42: Sweet, fruity, apples | Q42: 0 | U42: Sweet, fruity, apples | AG42: 1
B44: Acetaldehyde (green apples, peel) | R44: Acetaldehyde (green apples, peel)
Q45: =IF(ISBLANK(O45),IF(ISBLANK(M45),IF(ISBLANK(K45),IF(ISBLANK(I45),IF(ISBLANK(G45),IF(ISBLANK(E45),0,1),2),3),4),5),6) | AG45: =IF(ISBLANK(AE45),IF(ISBLANK(AC45),IF(ISBLANK(AA45),IF(ISBLANK(Y45),IF(ISBLANK(W45),IF(ISBLANK(U45),0,1),2),3),4),5),6)
C46: 0 | E46: 1 | G46: 2 | I46: 3 | K46: 4 | M46: 5 | O46: 6 | S46: 0 | U46: 1 | W46: 2 | Y46: 3 | AA46: 4 | AC46: 5 | AE46: 6
B49: Body | R49: Alcohol
Q50: 3 | AG50: 4
C51: 0 | E51: 1 | G51: 2 | I51: 3 | K51: 4 | M51: 5 | O51: 6 | S51: 0 | U51: 1 | W51: 2 | Y51: 3 | AA51: 4 | AC51: 5 | AE51: 6
B53: Bitterness | R53: Sweetness
Q54: 3 | AG54: 1
C55: 0 | E55: 1 | G55: 2 | I55: 3 | K55: 4 | M55: 5 | O55: 6 | S55: 0 | U55: 1 | W55: 2 | Y55: 3 | AA55: 4 | AC55: 5 | AE55: 6
B57: Carbonation | R57: Acidity/sourness
Q58: 3 | AG58: 1
C59: 0 | E59: 1 | G59: 2 | I59: 3 | K59: 4 | M59: 5 | O59: 6 | S59: 0 | U59: 1 | W59: 2 | Y59: 3 | AA59: 4 | AC59: 5 | AE59: 6
B61: Aftertaste
Q62: 4 | AG62: =IF(ISBLANK(AE62),IF(ISBLANK(AC62),IF(ISBLANK(AA62),IF(ISBLANK(Y62),IF(ISBLANK(W62),IF(ISBLANK(U62),0,1),2),3),4),5),6)
C63: 0 | E63: 1 | G63: 2 | I63: 3 | K63: 4 | M63: 5 | O63: 6
B66: Faults
...

Sheet beer_10
B1: Date
B3: Name: | R3: Beer#: | S3: 10
B5: Aroma | R5: Flavour
B6: Malt | R6: Malt
Q7: 1 | AG7: 1
C8: 0 | E8: 1 | G8: 2 | I8: 3 | K8: 4 | M8: 5 | O8: 6 | S8: 0 | U8: 1 | W8: 2 | Y8: 3 | AA8: 4 | AC8: 5 | AE8: 6
E10: Cereals, flour, grains | Q10: 3 | U10: Cereals, flour, grains | AG10: 3
E12: Bread crust | Q12: 1 | U12: Bread crust | AG12: 1
E14: Caramel | Q14: 1 | U14: Caramel | AG14: 0
E16: Smoked, burnt toast | Q16: 0 | U16: Smoked, burnt toast | AG16: 0
B19: Hops | R19: Hops
Q20: 1 | AG20: 0
C21: 0 | E21: 1 | G21: 2 | I21: 3 | K21: 4 | M21: 5 | O21: 6 | S21: 0 | U21: 1 | W21: 2 | Y21: 3 | AA21: 4 | AC21: 5 | AE21: 6
E23: Citrus | Q23: 1 | U23: Citrus | AG23: 1
E25: Tropical fruit | Q25: 0 | U25: Tropical fruit | AG25: 0
E27: Noble hops (dried herbs, dried grass, hay) | Q27: 0 | U27: Noble hops (dried herbs, dried grass, hay) | AG27: 1
E29: Pine, woody, resinous | Q29: 1 | U29: Pine, woody, resinous | AG29: 0
B32: Esters | R32: Esters
Q33: 2 | AG33: 1
C34: 0 | E34: 1 | G34: 2 | I34: 3 | K34: 4 | M34: 5 | O34: 6 | S34: 0 | U34: 1 | W34: 2 | Y34: 3 | AA34: 4 | AC34: 5 | AE34: 6
E36: Ethyl acetate, solvent, nail polish | Q36: 0 | U36: Ethyl acetate, solvent, nail polish | AG36: 0
E38: Banana, pear, candy | Q38: 1 | U38: Banana, pear, candy | AG38: 1
E40: Flowers, roses | Q40: 0 | U40: Flowers, roses | AG40: 1
E42: Sweet, fruity, apples | Q42: 0 | U42: Sweet, fruity, apples | AG42: 2
B44: Acetaldehyde (green apples, peel) | R44: Acetaldehyde (green apples, peel)
Q45: =IF(ISBLANK(O45),IF(ISBLANK(M45),IF(ISBLANK(K45),IF(ISBLANK(I45),IF(ISBLANK(G45),IF(ISBLANK(E45),0,1),2),3),4),5),6) | AG45: =IF(ISBLANK(AE45),IF(ISBLANK(AC45),IF(ISBLANK(AA45),IF(ISBLANK(Y45),IF(ISBLANK(W45),IF(ISBLANK(U45),0,1),2),3),4),5),6)
C46: 0 | E46: 1 | G46: 2 | I46: 3 | K46: 4 | M46: 5 | O46: 6 | S46: 0 | U46: 1 | W46: 2 | Y46: 3 | AA46: 4 | AC46: 5 | AE46: 6
B49: Body | R49: Alcohol
Q50: 2 | AG50: 2
C51: 0 | E51: 1 | G51: 2 | I51: 3 | K51: 4 | M51: 5 | O51: 6 | S51: 0 | U51: 1 | W51: 2 | Y51: 3 | AA51: 4 | AC51: 5 | AE51: 6
B53: Bitterness | R53: Sweetness
Q54: 1 | AG54: 2
C55: 0 | E55: 1 | G55: 2 | I55: 3 | K55: 4 | M55: 5 | O55: 6 | S55: 0 | U55: 1 | W55: 2 | Y55: 3 | AA55: 4 | AC55: 5 | AE55: 6
B57: Carbonation | R57: Acidity/sourness
Q58: 2 | AG58: 1
C59: 0 | E59: 1 | G59: 2 | I59: 3 | K59: 4 | M59: 5 | O59: 6 | S59: 0 | U59: 1 | W59: 2 | Y59: 3 | AA59: 4 | AC59: 5 | AE59: 6
B61: Aftertaste
Q62: 2 | AG62: =IF(ISBLANK(AE62),IF(ISBLANK(AC62),IF(ISBLANK(AA62),IF(ISBLANK(Y62),IF(ISBLANK(W62),IF(ISBLANK(U62),0,1),2),3),4),5),6)
C63: 0 | E63: 1 | G63: 2 | I63: 3 | K63: 4 | M63: 5 | O63: 6
B66: Faults
...

Sheet beer_11
B1: Date
B3: Name: | R3: Beer#: | S3: 11
B5: Aroma | R5: Flavour
B6: Malt | R6: Malt
Q7: 1 | AG7: 1
C8: 0 | E8: 1 | G8: 2 | I8: 3 | K8: 4 | M8: 5 | O8: 6 | S8: 0 | U8: 1 | W8: 2 | Y8: 3 | AA8: 4 | AC8: 5 | AE8: 6
E10: Cereals, flour, grains | Q10: 2 | U10: Cereals, flour, grains | AG10: 3
E12: Bread crust | Q12: 2 | U12: Bread crust | AG12: 1
E14: Caramel | Q14: 1 | U14: Caramel | AG14: 1
E16: Smoked, burnt toast | Q16: 0 | U16: Smoked, burnt toast | AG16: 1
B19: Hops | R19: Hops
Q20: 1 | AG20: 1
C21: 0 | E21: 1 | G21: 2 | I21: 3 | K21: 4 | M21: 5 | O21: 6 | S21: 0 | U21: 1 | W21: 2 | Y21: 3 | AA21: 4 | AC21: 5 | AE21: 6
E23: Citrus | Q23: 1 | U23: Citrus | AG23: 1
E25: Tropical fruit | Q25: 1 | U25: Tropical fruit | AG25: 0
E27: Noble hops (dried herbs, dried grass, hay) | Q27: 1 | U27: Noble hops (dried herbs, dried grass, hay) | AG27: 2
E29: Pine, woody, resinous | Q29: 1 | U29: Pine, woody, resinous | AG29: 0
B32: Esters | R32: Esters
Q33: 3 | AG33: 1
C34: 0 | E34: 1 | G34: 2 | I34: 3 | K34: 4 | M34: 5 | O34: 6 | S34: 0 | U34: 1 | W34: 2 | Y34: 3 | AA34: 4 | AC34: 5 | AE34: 6
E36: Ethyl acetate, solvent, nail polish | Q36: 1 | U36: Ethyl acetate, solvent, nail polish | AG36: 1
E38: Banana, pear, candy | Q38: 1 | U38: Banana, pear, candy | AG38: 1
E40: Flowers, roses | Q40: 1 | U40: Flowers, roses | AG40: 1
E42: Sweet, fruity, apples | Q42: 0 | U42: Sweet, fruity, apples | AG42: 1
B44: Acetaldehyde (green apples, peel) | R44: Acetaldehyde (green apples, peel)
Q45: =IF(ISBLANK(O45),IF(ISBLANK(M45),IF(ISBLANK(K45),IF(ISBLANK(I45),IF(ISBLANK(G45),IF(ISBLANK(E45),0,1),2),3),4),5),6) | AG45: =IF(ISBLANK(AE45),IF(ISBLANK(AC45),IF(ISBLANK(AA45),IF(ISBLANK(Y45),IF(ISBLANK(W45),IF(ISBLANK(U45),0,1),2),3),4),5),6)
C46: 0 | E46: 1 | G46: 2 | I46: 3 | K46: 4 | M46: 5 | O46: 6 | S46: 0 | U46: 1 | W46: 2 | Y46: 3 | AA46: 4 | AC46: 5 | AE46: 6
B49: Body | R49: Alcohol
Q50: 3 | AG50: 4
C51: 0 | E51: 1 | G51: 2 | I51: 3 | K51: 4 | M51: 5 | O51: 6 | S51: 0 | U51: 1 | W51: 2 | Y51: 3 | AA51: 4 | AC51: 5 | AE51: 6
B53: Bitterness | R53: Sweetness
Q54: 3 | AG54: 2
C55: 0 | E55: 1 | G55: 2 | I55: 3 | K55: 4 | M55: 5 | O55: 6 | S55: 0 | U55: 1 | W55: 2 | Y55: 3 | AA55: 4 | AC55: 5 | AE55: 6
B57: Carbonation | R57: Acidity/sourness
Q58: 3 | AG58: 1
C59: 0 | E59: 1 | G59: 2 | I59: 3 | K59: 4 | M59: 5 | O59: 6 | S59: 0 | U59: 1 | W59: 2 | Y59: 3 | AA59: 4 | AC59: 5 | AE59: 6
B61: Aftertaste
Q62: 4 | AG62: =IF(ISBLANK(AE62),IF(ISBLANK(AC62),IF(ISBLANK(AA62),IF(ISBLANK(Y62),IF(ISBLANK(W62),IF(ISBLANK(U62),0,1),2),3),4),5),6)
C63: 0 | E63: 1 | G63: 2 | I63: 3 | K63: 4 | M63: 5 | O63: 6
B66: Faults
...

Sheet beer_12
B1: Date
B3: Name: | R3: Beer#: | S3: 12
B5: Aroma | R5: Flavour
B6: Malt | R6: Malt
Q7: 1 | AG7: 1
C8: 0 | E8: 1 | G8: 2 | I8: 3 | K8: 4 | M8: 5 | O8: 6 | S8: 0 | U8: 1 | W8: 2 | Y8: 3 | AA8: 4 | AC8: 5 | AE8: 6
E10: Cereals, flour, grains | Q10: 2 | U10: Cereals, flour, grains | AG10: 3
E12: Bread crust | Q12: 1 | U12: Bread crust | AG12: 1
E14: Caramel | Q14: 1 | U14: Caramel | AG14: 1
E16: Smoked, burnt toast | Q16: 0 | U16: Smoked, burnt toast | AG16: 0
B19: Hops | R19: Hops
Q20: 1 | AG20: 0
C21: 0 | E21: 1 | G21: 2 | I21: 3 | K21: 4 | M21: 5 | O21: 6 | S21: 0 | U21: 1 | W21: 2 | Y21: 3 | AA21: 4 | AC21: 5 | AE21: 6
E23: Citrus | Q23: 1 | U23: Citrus | AG23: 1
E25: Tropical fruit | Q25: 0 | U25: Tropical fruit | AG25: 0
E27: Noble hops (dried herbs, dried grass, hay) | Q27: 0 | U27: Noble hops (dried herbs, dried grass, hay) | AG27: 1
E29: Pine, woody, resinous | Q29: 1 | U29: Pine, woody, resinous | AG29: 0
B32: Esters | R32: Esters
Q33: 4 | AG33: 2
C34: 0 | E34: 1 | G34: 2 | I34: 3 | K34: 4 | M34: 5 | O34: 6 | S34: 0 | U34: 1 | W34: 2 | Y34: 3 | AA34: 4 | AC34: 5 | AE34: 6
E36: Ethyl acetate, solvent, nail polish | Q36: 1 | U36: Ethyl acetate, solvent, nail polish | AG36: 1
E38: Banana, pear, candy | Q38: 1 | U38: Banana, pear, candy | AG38: 2
E40: Flowers, roses | Q40: 2 | U40: Flowers, roses | AG40: 1
E42: Sweet, fruity, apples | Q42: 1 | U42: Sweet, fruity, apples | AG42: 2
B44: Acetaldehyde (green apples, peel) | R44: Acetaldehyde (green apples, peel)
Q45: =IF(ISBLANK(O45),IF(ISBLANK(M45),IF(ISBLANK(K45),IF(ISBLANK(I45),IF(ISBLANK(G45),IF(ISBLANK(E45),0,1),2),3),4),5),6) | AG45: =IF(ISBLANK(AE45),IF(ISBLANK(AC45),IF(ISBLANK(AA45),IF(ISBLANK(Y45),IF(ISBLANK(W45),IF(ISBLANK(U45),0,1),2),3),4),5),6)
C46: 0 | E46: 1 | G46: 2 | I46: 3 | K46: 4 | M46: 5 | O46: 6 | S46: 0 | U46: 1 | W46: 2 | Y46: 3 | AA46: 4 | AC46: 5 | AE46: 6
B49: Body | R49: Alcohol
Q50: 3 | AG50: 3
C51: 0 | E51: 1 | G51: 2 | I51: 3 | K51: 4 | M51: 5 | O51: 6 | S51: 0 | U51: 1 | W51: 2 | Y51: 3 | AA51: 4 | AC51: 5 | AE51: 6
B53: Bitterness | R53: Sweetness
Q54: 1 | AG54: 2
C55: 0 | E55: 1 | G55: 2 | I55: 3 | K55: 4 | M55: 5 | O55: 6 | S55: 0 | U55: 1 | W55: 2 | Y55: 3 | AA55: 4 | AC55: 5 | AE55: 6
B57: Carbonation | R57: Acidity/sourness
Q58: 2 | AG58: 2
C59: 0 | E59: 1 | G59: 2 | I59: 3 | K59: 4 | M59: 5 | O59: 6 | S59: 0 | U59: 1 | W59: 2 | Y59: 3 | AA59: 4 | AC59: 5 | AE59: 6
B61: Aftertaste
Q62: 3 | AG62: =IF(ISBLANK(AE62),IF(ISBLANK(AC62),IF(ISBLANK(AA62),IF(ISBLANK(Y62),IF(ISBLANK(W62),IF(ISBLANK(U62),0,1),2),3),4),5),6)
C63: 0 | E63: 1 | G63: 2 | I63: 3 | K63: 4 | M63: 5 | O63: 6
B66: Faults
...

Sheet summary
A1: Beer | B1: A_malt_all | C1: A_malt_grain | D1: A_malt_bread | E1: A_malt_cara | F1: A_malt_burn | G1: A_hops_all | H1: A_hops_citrus | I1: A_hops_tropical | J1: A_hops_noble | K1: A_hops_woody | L1: A_esters_all | M1: A_esters_ethac | N1: A_esters_isoaa | O1: A_esters_flower | P1: A_ester_fruity | Q1: F_malt_all | R1: F_malt_grain | S1: F_malt_bread | T1: F_malt_cara | U1: F_malt_burn | V1: F_hops_all | W1: F_hops_citrus | X1: F_hops_tropical | Y1: F_hops_noble | Z1: F_hops_woody | AA1: F_esters_all | AB1: F_esters_ethac | AC1: F_esters_isoaa | AD1: F_esters_flower | AE1: F_ester_fruity | AF1: body | AG1: bitternes | AH1: co2 | AI1: aftertaste | AJ1: alcohol | AK1: sweetness | AL1: acidity | AM1: dms | AN1: metallic | AO1: 4vg | AP1: t2n | AQ1: diacetyl | AR1: stale_hops | AS1: orange | AT1: coriander | AU1: clove | AV1: lactic | AW1: acetic | AX1: barnyard | AY1: overall | AZ1: comments
A2: 1 | B2: 1 | C2: 2 | D2: 2 | E2: 1 | F2: 0 | G2: 2 | H2: 1 | I2: 1 | J2: 1 | K2: 1 | L2: 3 | M2: 2 | N2: 1 | O2: 1 | P2: 0 | Q2: 1 | R2: 3 | S2: 1 | T2: 0 | U2: 1 | V2: 2 | W2: 1 | X2: 1 | Y2: 2 | Z2: 1 | AA2: 2 | AB2: 2 | AC2: 1 | AD2: 1 | AE2: 1 | AF2: 4 | AG2: 3 | AH2: 3 | AI2: 4 | AJ2: 4 | AK2: 1 | AL2: 1 | AM2: 1 | AN2: 2 | AO2: =beer_1!$Q$76 | AP2: 1 | AQ2: 2 | AR2: 0 | AS2: 0 | AT2: 1 | AU2: 0 | AV2: 1 | AW2: 1 | AX2: 0 | AY2: 4 | AZ2: =beer_1!$S$93
A3: 2 | B3: 1 | C3: 3 | D3: 1 | E3: 0 | F3: 0 | G3: 0 | H3: 1 | I3: 0 | J3: 0 | K3: 1 | L3: 2 | M3: 0 | N3: 0 | O3: 0 | P3: 0 | Q3: 1 | R3: 3 | S3: 1 | T3: 0 | U3: 0 | V3: 0 | W3: 1 | X3: 0 | Y3: 1 | Z3: 0 | AA3: 0 | AB3: 0 | AC3: 1 | AD3: 0 | AE3: 1 | AF3: 2 | AG3: 1 | AH3: 1 | AI3: 2 | AJ3: 1 | AK3: 2 | AL3: 1 | AM3: 0 | AN3: 1 | AO3: =beer_2!$Q$76 | AP3: 1 | AQ3: 2 | AR3: 0 | AS3: 0 | AT3: 1 | AU3: 0 | AV3: 1 | AW3: 1 | AX3: 0 | AY3: 2 | AZ3: =beer_2!$S$93
A4: 3 | B4: 1 | C4: 2 | D4: 1 | E4: 1 | F4: 0 | G4: 1 | H4: 1 | I4: 0 | J4: 1 | K4: 1 | L4: 3 | M4: 1 | N4: 1 | O4: 1 | P4: 0 | Q4: 1 | R4: 3 | S4: 1 | T4: 0 | U4: 0 | V4: 1 | W4: 1 | X4: 0 | Y4: 1 | Z4: 0 | AA4: 1 | AB4: 1 | AC4: 1 | AD4: 1 | AE4: 1 | AF4: 3 | AG4: 2 | AH4: 2 | AI4: 3 | AJ4: 4 | AK4: 2 | AL4: 1 | AM4: 1 | AN4: 3 | AO4: =beer_3!$Q$76 | AP4: 1 | AQ4: 2 | AR4: 0 | AS4: 0 | AT4: 1 | AU4: 0 | AV4: 1 | AW4: 1 | AX4: 0 | AY4: 3 | AZ4: =beer_3!$S$93
A5: 4 | B5: 2 | C5: 3 | D5: 2 | E5: 2 | F5: 1 | G5: 2 | H5: 1 | I5: 1 | J5: 1 | K5: 1 | L5: 4 | M5: 2 | N5: 2 | O5: 1 | P5: 1 | Q5: 2 | R5: 4 | S5: 2 | T5: 1 | U5: 1 | V5: 2 | W5: 1 | X5: 1 | Y5: 2 | Z5: 1 | AA5: 2 | AB5: 2 | AC5: 2 | AD5: 1 | AE5: 2 | AF5: 4 | AG5: 3 | AH5: 3 | AI5: 4 | AJ5: 5 | AK5: 2 | AL5: 1 | AM5: 0 | AN5: 2 | AO5: =beer_4!$Q$76 | AP5: 1 | AQ5: 2 | AR5: 0 | AS5: 0 | AT5: 1 | AU5: 0 | AV5: 1 | AW5: 1 | AX5: 0 | AY5: 4 | AZ5: =beer_4!$S$93
A6: 5 | B6: 1 | C6: 2 | D6: 2 | E6: 1 | F6: 0 | G6: 2 | H6: 2 | I6: 1 | J6: 2 | K6: 2 | L6: 3 | M6: 1 | N6: 1 | O6: 1 | P6: 0 | Q6: 1 | R6: 3 | S6: 1 | T6: 0 | U6: 1 | V6: 2 | W6: 2 | X6: 1 | Y6: 2 | Z6: 1 | AA6: 1 | AB6: 1 | AC6: 1 | AD6: 1 | AE6: 1 | AF6: 3 | AG6: 4 | AH6: 3 | AI6: 4 | AJ6: 4 | AK6: 1 | AL6: 1 | AM6: 0 | AN6: 2 | AO6: =beer_5!$Q$76 | AP6: 1 | AQ6: 1 | AR6: 1 | AS6: 0 | AT6: 1 | AU6: 0 | AV6: 1 | AW6: 1 | AX6: 1 | AY6: 4 | AZ6: =beer_5!$S$93
A7: 6 | B7: 1 | C7: 2 | D7: 2 | E7: 1 | F7: 0 | G7: 2 | H7: 1 | I7: 1 | J7: 1 | K7: 1 | L7: 3 | M7: 1 | N7: 1 | O7: 1 | P7: 0 | Q7: 1 | R7: 3 | S7: 1 | T7: 1 | U7: 1 | V7: 1 | W7: 1 | X7: 0 | Y7: 2 | Z7: 1 | AA7: 1 | AB7: 1 | AC7: 1 | AD7: 1 | AE7: 1 | AF7: 3 | AG7: 3 | AH7: 3 | AI7: 4 | AJ7: 4 | AK7: 2 | AL7: 1 | AM7: 1 | AN7: 2 | AO7: =beer_6!$Q$76 | AP7: 1 | AQ7: 2 | AR7: 0 | AS7: 0 | AT7: 1 | AU7: 0 | AV7: 1 | AW7: 1 | AX7: 1 | AY7: 4 | AZ7: =beer_6!$S$93
A8: 7 | B8: 0 | C8: 2 | D8: 1 | E8: 1 | F8: 0 | G8: 2 | H8: 2 | I8: 1 | J8: 1 | K8: 1 | L8: 3 | M8: 1 | N8: 1 | O8: 1 | P8: 0 | Q8: 1 | R8: 3 | S8: 1 | T8: 0 | U8: 0 | V8: 2 | W8: 1 | X8: 1 | Y8: 2 | Z8: 1 | AA8: 1 | AB8: 1 | AC8: 1 | AD8: 1 | AE8: 2 | AF8: 3 | AG8: 3 | AH8: 3 | AI8: 4 | AJ8: 4 | AK8: 2 | AL8: 1 | AM8: 0 | AN8: 2 | AO8: =beer_7!$Q$76 | AP8: 1 | AQ8: 2 | AR8: 0 | AS8: 0 | AT8: 2 | AU8: 0 | AV8: 1 | AW8: 1 | AX8: 0 | AY8: 4 | AZ8: =beer_7!$S$93
A9: 8 | B9: 1 | C9: 2 | D9: 2 | E9: 1 | F9: 0 | G9: 2 | H9: 1 | I9: 1 | J9: 1 | K9: 1 | L9: 4 | M9: 2 | N9: 1 | O9: 1 | P9: 0 | Q9: 2 | R9: 3 | S9: 2 | T9: 1 | U9: 1 | V9: 2 | W9: 1 | X9: 0 | Y9: 2 | Z9: 1 | AA9: 2 | AB9: 2 | AC9: 1 | AD9: 1 | AE9: 1 | AF9: 4 | AG9: 3 | AH9: 3 | AI9: 4 | AJ9: 5 | AK9: 1 | AL9: 1 | AM9: 1 | AN9: 2 | AO9: =beer_8!$Q$76 | AP9: 1 | AQ9: 2 | AR9: 0 | AS9: 0 | AT9: 1 | AU9: 0 | AV9: 1 | AW9: 1 | AX9: 0 | AY9: 4 | AZ9: =beer_8!$S$93
A10: 9 | B10: 1 | C10: 2 | D10: 2 | E10: 1 | F10: 0 | G10: 2 | H10: 2 | I10: 1 | J10: 1 | K10: 2 | L10: 3 | M10: 2 | N10: 1 | O10: 1 | P10: 0 | Q10: 1 | R10: 3 | S10: 1 | T10: 0 | U10: 1 | V10: 2 | W10: 1 | X10: 1 | Y10: 2 | Z10: 1 | AA10: 1 | AB10: 1 | AC10: 1 | AD10: 1 | AE10: 1 | AF10: 3 | AG10: 3 | AH10: 3 | AI10: 4 | AJ10: 4 | AK10: 1 | AL10: 1 | AM10: 0 | AN10: 2 | AO10: =beer_9!$Q$76 | AP10: 1 | AQ10: 1 | AR10: 1 | AS10: 0 | AT10: 1 | AU10: 0 | AV10: 1 | AW10: 1 | AX10: 1 | AY10: 4 | AZ10: =beer_9!$S$93
A11: 10 | B11: 1 | C11: 3 | D11: 1 | E11: 1 | F11: 0 | G11: 1 | H11: 1 | I11: 0 | J11: 0 | K11: 1 | L11: 2 | M11: 0 | N11: 1 | O11: 0 | P11: 0 | Q11: 1 | R11: 3 | S11: 1 | T11: 0 | U11: 0 | V11: 0 | W11: 1 | X11: 0 | Y11: 1 | Z11: 0 | AA11: 1 | AB11: 0 | AC11: 1 | AD11: 1 | AE11: 2 | AF11: 2 | AG11: 1 | AH11: 2 | AI11: 2 | AJ11: 2 | AK11: 2 | AL11: 1 | AM11: 1 | AN11: 2 | AO11: =beer_10!$Q$76 | AP11: 1 | AQ11: 2 | AR11: 0 | AS11: 1 | AT11: 2 | AU11: 0 | AV11: 2 | AW11: 1 | AX11: 0 | AY11: 2 | AZ11: =beer_10!$S$93
A12: 11 | B12: 1 | C12: 2 | D12: 2 | E12: 1 | F12: 0 | G12: 1 | H12: 1 | I12: 1 | J12: 1 | K12: 1 | L12: 3 | M12: 1 | N12: 1 | O12: 1 | P12: 0 | Q12: 1 | R12: 3 | S12: 1 | T12: 1 | U12: 1 | V12: 1 | W12: 1 | X12: 0 | Y12: 2 | Z12: 0 | AA12: 1 | AB12: 1 | AC12: 1 | AD12: 1 | AE12: 1 | AF12: 3 | AG12: 3 | AH12: 3 | AI12: 4 | AJ12: 4 | AK12: 2 | AL12: 1 | AM12: 1 | AN12: 2 | AO12: =beer_11!$Q$76 | AP12: 1 | AQ12: 2 | AR12: 0 | AS12: 0 | AT12: 1 | AU12: 0 | AV12: 1 | AW12: 1 | AX12: 0 | AY12: 4 | AZ12: =beer_11!$S$93
A13: 12 | B13: 1 | C13: 2 | D13: 1 | E13: 1 | F13: 0 | G13: 1 | H13: 1 | I13: 0 | J13: 0 | K13: 1 | L13: 4 | M13: 1 | N13: 1 | O13: 2 | P13: 1 | Q13: 1 | R13: 3 | S13: 1 | T13: 1 | U13: 0 | V13: 0 | W13: 1 | X13: 0 | Y13: 1 | Z13: 0 | AA13: 2 | AB13: 1 | AC13: 2 | AD13: 1 | AE13: 2 | AF13: 3 | AG13: 1 | AH13: 2 | AI13: 3 | AJ13: 3 | AK13: 2 | AL13: 2 | AM13: 0 | AN13: 2 | AO13: =beer_12!$Q$76 | AP13: 1 | AQ13: 2 | AR13: 0 | AS13: 0 | AT13: 1 | AU13: 0 | AV13: 2 | AW13: 2 | AX13: 0 | AY13: 3 | AZ13: =beer_12!$S$93
